Workbook
Name _75: OFFSET('Buy List'!$V$3,'Buy List'!$Q$4*'Buy List'!$Q$27,,COUNT('Buy List'!$V$3:$V$502),)
Name _80: OFFSET('Buy List'!$W$3,'Buy List'!$Q$4*'Buy List'!$Q$27,,COUNT('Buy List'!$W$3:$W$502),)
Name _85: OFFSET('Buy List'!$X$3,'Buy List'!$Q$4*'Buy List'!$Q$27,,COUNT('Buy List'!$X$3:$X$502),)
Name _90: OFFSET('Buy List'!$Y$3,'Buy List'!$Q$4*'Buy List'!$Q$27,,COUNT('Buy List'!$Y$3:$Y$502),)
Name KeepList: Table1[]
Name Prob: OFFSET('Buy List'!$U$3,'Buy List'!$Q$4*'Buy List'!$Q$27,,COUNT('Buy List'!$U$3:$U$502),)
Name Spectrum: OFFSET('Buy List'!$T$3,'Buy List'!$Q$4*'Buy List'!$Q$27,,COUNT('Buy List'!$T$3:$T$502),)

Sheet Purchase Log
P1: Shipping | Q1: Price | R1: Tax
P2: =SUM(G:G) -> 197.81 | Q2: =SUM(F:F) -> 1327.41 | R2: =SUM(H:H) -> 149.485
B3: Status | C3: Seller | D3: Date Purchased | E3: Show# | F3: Price | G3: Shipping | H3: Tax | I3: Player | J3: ID | K3: Item # | L3: Link | M3: TEXT | N3: CONCAT | O3: WhatNot Total | P3: Adjusted Shipping | Q3: Adjusted Price/Shipping | R3: Adjusted Tax | S3: Adjusted Total | T3: Value | U3: Variance | V3: Count | W3: Set | X3: Description | Y3: Notes | AB3: Row Labels | AC3: Sum of Variance
B4: R | C4: Hoot2000 | D4: 46145 | E4: 33 | F4: 7 | G4: 4.11 | H4: 1.14 | I4: Wembanyama | J4: 6059255 | K4: 108 | L4: https://www.whatnot.com/order/Hqs3wb8GAkuyHj9LA3xEdv | M4: whatnot.com/order/Hqs3wb8GAkuyHj9LA3xEdv $7.00 + $1.14 (Shared Shipping) + $0.83 Tax = Total of $8.97 | N4: =IFERROR(_xlfn.TEXTAFTER(L4,"https://www."),"")&CHAR(10)&_xlfn.CONCAT(TEXT(F4,"$0.00")," + ",TEXT(P4,"$0.00")," (Shared Shipping) + ",TEXT(R4,"$0.00")," Tax = Total of ",TEXT(S4,"$0.00")) -> whatnot.com/order/Hqs3wb8GAkuyHj9LA3xEdv $7.00 + $1.14 (Shared Shipping) + $0.83 Tax = Total of $8.97 | O4: =SUM(F4:H4) -> 12.25 | P4: =SUMIFS(G:G,C:C,C4,D:D,D4)/COUNTIFS(C:C,C4,D:D,D4) -> 1.1375 | Q4: =+F4+P4 -> 8.1375 | R4: =IF(H4=0,0,Q4*0.1025) -> 0.83409375 | S4: =+Q4+R4 -> 8.9715937 | T4: =IFERROR(_xlfn.XLOOKUP(J4,Collection!A:A,Collection!D:D,0)/100/_xlfn.XLOOKUP(J4,Collection!A:A,Collection!J:J,0),_xlfn.XLOOKUP(J4,Sold!A:A,Sold!D:D,0)/100/_xlfn.XLOOKUP(J4,Sold!A:A,Sold!J:J,0)) -> 6.47 | U4: =IFERROR(T4-S4,0) -> -2.5015937 | V4: =COUNTIF(Collection!A:A,J4)+COUNTIF(Sold!A:A,J4) -> 1 | W4: =IFERROR(_xlfn.TEXTAFTER(_xlfn.XLOOKUP(J4,Collection!A:A,Collection!C:C,),"Cards "),_xlfn.TEXTAFTER(_xlfn.XLOOKUP(J4,Sold!A:A,Sold!C:C,),"Cards ")) -> 2023 Panini Hoops | X4: =IFERROR(_xlfn.XLOOKUP(J4,Collection!A:A,Collection!B:B,),_xlfn.XLOOKUP(J4,Sold!A:A,Sold!B:B,)) -> Victor Wembanyama #298 | Y4: . | AB4: jaytheselller | AC4: 30.518475
B5: R | C5: Hoot2000 | D5: 46145 | E5: 35 | F5: 8 | G5: 0.44 | H5: 0.87 | I5: Wembanyama | J5: 12415755 | K5: 90 | L5: https://www.whatnot.com/order/ATFJnWBvkv75frTYPbgk5o | M5: whatnot.com/order/ATFJnWBvkv75frTYPbgk5o $8.00 + $1.14 (Shared Shipping) + $0.94 Tax = Total of $10.07 | N5: =IFERROR(_xlfn.TEXTAFTER(L5,"https://www."),"")&CHAR(10)&_xlfn.CONCAT(TEXT(F5,"$0.00")," + ",TEXT(P5,"$0.00")," (Shared Shipping) + ",TEXT(R5,"$0.00")," Tax = Total of ",TEXT(S5,"$0.00")) -> whatnot.com/order/ATFJnWBvkv75frTYPbgk5o $8.00 + $1.14 (Shared Shipping) + $0.94 Tax = Total of $10.07 | O5: =SUM(F5:H5) -> 9.31 | P5: =SUMIFS(G:G,C:C,C5,D:D,D5)/COUNTIFS(C:C,C5,D:D,D5) -> 1.1375 | Q5: =+F5+P5 -> 9.1375 | R5: =IF(H5=0,0,Q5*0.1025) -> 0.93659375 | S5: =+Q5+R5 -> 10.074094 | T5: =IFERROR(_xlfn.XLOOKUP(J5,Collection!A:A,Collection!D:D,0)/100/_xlfn.XLOOKUP(J5,Collection!A:A,Collection!J:J,0),_xlfn.XLOOKUP(J5,Sold!A:A,Sold!D:D,0)/100/_xlfn.XLOOKUP(J5,Sold!A:A,Sold!J:J,0)) -> 9.49 | U5: =IFERROR(T5-S5,0) -> -0.58409375 | V5: =COUNTIF(Collection!A:A,J5)+COUNTIF(Sold!A:A,J5) -> 1 | W5: =IFERROR(_xlfn.TEXTAFTER(_xlfn.XLOOKUP(J5,Collection!A:A,Collection!C:C,),"Cards "),_xlfn.TEXTAFTER(_xlfn.XLOOKUP(J5,Sold!A:A,Sold!C:C,),"Cards ")) -> 2026 Topps Collectors Kit | X5: =IFERROR(_xlfn.XLOOKUP(J5,Collection!A:A,Collection!B:B,),_xlfn.XLOOKUP(J5,Sold!A:A,Sold!B:B,)) -> Victor Wembanyama [Wave] #NBA-7 | Y5: . | AB5: jayspopup | AC5: 25.520133
B6: R | C6: Hoot2000 | D6: 46145 | E6: 44 | F6: 3 | G6: 0 | H6: 0.31 | I6: James | J6: 10826665 | K6: 55 | L6: https://www.whatnot.com/order/R4eDqBQtSQwNRiU33sZje5 | M6: whatnot.com/order/R4eDqBQtSQwNRiU33sZje5 $3.00 + $1.14 (Shared Shipping) + $0.42 Tax = Total of $4.56 | N6: =IFERROR(_xlfn.TEXTAFTER(L6,"https://www."),"")&CHAR(10)&_xlfn.CONCAT(TEXT(F6,"$0.00")," + ",TEXT(P6,"$0.00")," (Shared Shipping) + ",TEXT(R6,"$0.00")," Tax = Total of ",TEXT(S6,"$0.00")) -> whatnot.com/order/R4eDqBQtSQwNRiU33sZje5 $3.00 + $1.14 (Shared Shipping) + $0.42 Tax = Total of $4.56 | O6: =SUM(F6:H6) -> 3.31 | P6: =SUMIFS(G:G,C:C,C6,D:D,D6)/COUNTIFS(C:C,C6,D:D,D6) -> 1.1375 | Q6: =+F6+P6 -> 4.1375 | R6: =IF(H6=0,0,Q6*0.1025) -> 0.42409375 | S6: =+Q6+R6 -> 4.5615938 | T6: =IFERROR(_xlfn.XLOOKUP(J6,Collection!A:A,Collection!D:D,0)/100/_xlfn.XLOOKUP(J6,Collection!A:A,Collection!J:J,0),_xlfn.XLOOKUP(J6,Sold!A:A,Sold!D:D,0)/100/_xlfn.XLOOKUP(J6,Sold!A:A,Sold!J:J,0)) -> 3.25 | U6: =IFERROR(T6-S6,0) -> -1.3115938 | V6: =COUNTIF(Collection!A:A,J6)+COUNTIF(Sold!A:A,J6) -> 1 | W6: =IFERROR(_xlfn.TEXTAFTER(_xlfn.XLOOKUP(J6,Collection!A:A,Collection!C:C,),"Cards "),_xlfn.TEXTAFTER(_xlfn.XLOOKUP(J6,Sold!A:A,Sold!C:C,),"Cards ")) -> 2025 Topps | X6: =IFERROR(_xlfn.XLOOKUP(J6,Collection!A:A,Collection!B:B,),_xlfn.XLOOKUP(J6,Sold!A:A,Sold!B:B,)) -> LeBron James [Holo Foil] #150 | Y6: . | AB6: everydaysingles | AC6: 6.498275
B7: R | C7: Hoot2000 | D7: 46145 | E7: Givvy | F7: 0 | G7: 0 | H7: 0 | I7: Edgecombe | J7: 10895833 | K7: 478 | L7: https://www.whatnot.com/order/6QdgQ3vUdPh6pHE5WaqAmr | M7: whatnot.com/order/6QdgQ3vUdPh6pHE5WaqAmr $0.00 + $1.14 (Shared Shipping) + $0.12 Tax = Total of $1.25 | N7: =IFERROR(_xlfn.TEXTAFTER(L7,"https://www."),"")&CHAR(10)&_xlfn.CONCAT(TEXT(F7,"$0.00")," + ",TEXT(P7,"$0.00")," (Shared Shipping) + ",TEXT(R7,"$0.00")," Tax = Total of ",TEXT(S7,"$0.00")) -> whatnot.com/order/6QdgQ3vUdPh6pHE5WaqAmr $0.00 + $1.14 (Shared Shipping) + $0.00 Tax = Total of $1.14 | O7: =SUM(F7:H7) -> 0 | P7: =SUMIFS(G:G,C:C,C7,D:D,D7)/COUNTIFS(C:C,C7,D:D,D7) -> 1.1375 | Q7: =+F7+P7 -> 1.1375 | R7: =IF(H7=0,0,Q7*0.1025) -> 0 | S7: =+Q7+R7 -> 1.1375 | T7: =IFERROR(_xlfn.XLOOKUP(J7,Collection!A:A,Collection!D:D,0)/100/_xlfn.XLOOKUP(J7,Collection!A:A,Collection!J:J,0),_xlfn.XLOOKUP(J7,Sold!A:A,Sold!D:D,0)/100/_xlfn.XLOOKUP(J7,Sold!A:A,Sold!J:J,0)) -> 1.44 | U7: =IFERROR(T7-S7,0) -> 0.3025 | V7: =COUNTIF(Collection!A:A,J7)+COUNTIF(Sold!A:A,J7) -> 1 | W7: =IFERROR(_xlfn.TEXTAFTER(_xlfn.XLOOKUP(J7,Collection!A:A,Collection!C:C,),"Cards "),_xlfn.TEXTAFTER(_xlfn.XLOOKUP(J7,Sold!A:A,Sold!C:C,),"Cards ")) -> 2025 Topps Holiday | X7: =IFERROR(_xlfn.XLOOKUP(J7,Collection!A:A,Collection!B:B,),_xlfn.XLOOKUP(J7,Sold!A:A,Sold!B:B,)) -> VJ Edgecombe #H163 | Y7: . | AB7: plymouthsportscards | AC7: 5.2
B8: R | C8: kenjay_cards | D8: 46146 | E8: 144 | F8: 3 | G8: 1.09 | H8: 0.42 | I8: Chet | J8: 5475661 | K8: 451 | L8: https://www.whatnot.com/order/7TdKSNvxiGa3Bt8dCiKKbe | M8: whatnot.com/order/7TdKSNvxiGa3Bt8dCiKKbe $3.00 + $0.45 (Shared Shipping) + $0.35 Tax = Total of $3.81 | N8: =IFERROR(_xlfn.TEXTAFTER(L8,"https://www."),"")&CHAR(10)&_xlfn.CONCAT(TEXT(F8,"$0.00")," + ",TEXT(P8,"$0.00")," (Shared Shipping) + ",TEXT(R8,"$0.00")," Tax = Total of ",TEXT(S8,"$0.00")) -> whatnot.com/order/7TdKSNvxiGa3Bt8dCiKKbe $3.00 + $0.45 (Shared Shipping) + $0.35 Tax = Total of $3.81 | O8: =SUM(F8:H8) -> 4.51 | P8: =SUMIFS(G:G,C:C,C8,D:D,D8)/COUNTIFS(C:C,C8,D:D,D8) -> 0.45454545 | Q8: =+F8+P8 -> 3.4545455 | R8: =IF(H8=0,0,Q8*0.1025) -> 0.35409091 | S8: =+Q8+R8 -> 3.8086364 | T8: =IFERROR(_xlfn.XLOOKUP(J8,Collection!A:A,Collection!D:D,0)/100/_xlfn.XLOOKUP(J8,Collection!A:A,Collection!J:J,0),_xlfn.XLOOKUP(J8,Sold!A:A,Sold!D:D,0)/100/_xlfn.XLOOKUP(J8,Sold!A:A,Sold!J:J,0)) -> 1.42 | U8: =IFERROR(T8-S8,0) -> -2.3886364 | V8: =COUNTIF(Collection!A:A,J8)+COUNTIF(Sold!A:A,J8) -> 1 | W8: =IFERROR(_xlfn.TEXTAFTER(_xlfn.XLOOKUP(J8,Collection!A:A,Collection!C:C,),"Cards "),_xlfn.TEXTAFTER(_xlfn.XLOOKUP(J8,Sold!A:A,Sold!C:C,),"Cards ")) -> 2022 Panini Select Rookie Revolution | X8: =IFERROR(_xlfn.XLOOKUP(J8,Collection!A:A,Collection!B:B,),_xlfn.XLOOKUP(J8,Sold!A:A,Sold!B:B,)) -> Chet Holmgren #18 | Y8: . | AB8: freddievar84 | AC8: 3.476125
B9: R | C9: kenjay_cards | D9: 46146 | E9: 159 | F9: 4 | G9: 0.3 | H9: 0.45 | I9: Luka | J9: 4235113 | K9: 411 | L9: https://www.whatnot.com/order/A2VyUVWvtd6f5zu7wQpMgK | M9: whatnot.com/order/A2VyUVWvtd6f5zu7wQpMgK $4.00 + $0.45 (Shared Shipping) + $0.46 Tax = Total of $4.91 | N9: =IFERROR(_xlfn.TEXTAFTER(L9,"https://www."),"")&CHAR(10)&_xlfn.CONCAT(TEXT(F9,"$0.00")," + ",TEXT(P9,"$0.00")," (Shared Shipping) + ",TEXT(R9,"$0.00")," Tax = Total of ",TEXT(S9,"$0.00")) -> whatnot.com/order/A2VyUVWvtd6f5zu7wQpMgK $4.00 + $0.45 (Shared Shipping) + $0.46 Tax = Total of $4.91 | O9: =SUM(F9:H9) -> 4.75 | P9: =SUMIFS(G:G,C:C,C9,D:D,D9)/COUNTIFS(C:C,C9,D:D,D9) -> 0.45454545 | Q9: =+F9+P9 -> 4.4545455 | R9: =IF(H9=0,0,Q9*0.1025) -> 0.45659091 | S9: =+Q9+R9 -> 4.9111364 | T9: =IFERROR(_xlfn.XLOOKUP(J9,Collection!A:A,Collection!D:D,0)/100/_xlfn.XLOOKUP(J9,Collection!A:A,Collection!J:J,0),_xlfn.XLOOKUP(J9,Sold!A:A,Sold!D:D,0)/100/_xlfn.XLOOKUP(J9,Sold!A:A,Sold!J:J,0)) -> 1.27 | U9: =IFERROR(T9-S9,0) -> -3.6411364 | V9: =COUNTIF(Collection!A:A,J9)+COUNTIF(Sold!A:A,J9) -> 1 | W9: =IFERROR(_xlfn.TEXTAFTER(_xlfn.XLOOKUP(J9,Collection!A:A,Collection!C:C,),"Cards "),_xlfn.TEXTAFTER(_xlfn.XLOOKUP(J9,Sold!A:A,Sold!C:C,),"Cards ")) -> 2021 Panini Select | X9: =IFERROR(_xlfn.XLOOKUP(J9,Collection!A:A,Collection!B:B,),_xlfn.XLOOKUP(J9,Sold!A:A,Sold!B:B,)) -> Luka Doncic [Blue Prizm] #12 | Y9: . | AB9: cardboardbeast | AC9: 2.565
B10: R | C10: kenjay_cards | D10: 46146 | E10: 223 | F10: 4 | G10: 2.96 | H10: 0.71 | I10: Luka | J10: 4116797 | K10: 397 | L10: https://www.whatnot.com/order/UfG2uFVzbc3XCQZDoAnZnQ | M10: whatnot.com/order/UfG2uFVzbc3XCQZDoAnZnQ $4.00 + $0.45 (Shared Shipping) + $0.46 Tax = Total of $4.91 | N10: =IFERROR(_xlfn.TEXTAFTER(L10,"https://www."),"")&CHAR(10)&_xlfn.CONCAT(TEXT(F10,"$0.00")," + ",TEXT(P10,"$0.00")," (Shared Shipping) + ",TEXT(R10,"$0.00")," Tax = Total of ",TEXT(S10,"$0.00")) -> whatnot.com/order/UfG2uFVzbc3XCQZDoAnZnQ $4.00 + $0.45 (Shared Shipping) + $0.46 Tax = Total of $4.91 | O10: =SUM(F10:H10) -> 7.67 | P10: =SUMIFS(G:G,C:C,C10,D:D,D10)/COUNTIFS(C:C,C10,D:D,D10) -> 0.45454545 | Q10: =+F10+P10 -> 4.4545455 | R10: =IF(H10=0,0,Q10*0.1025) -> 0.45659091 | S10: =+Q10+R10 -> 4.9111364 | T10: =IFERROR(_xlfn.XLOOKUP(J10,Collection!A:A,Collection!D:D,0)/100/_xlfn.XLOOKUP(J10,Collection!A:A,Collection!J:J,0),_xlfn.XLOOKUP(J10,Sold!A:A,Sold!D:D,0)/100/_xlfn.XLOOKUP(J10,Sold!A:A,Sold!J:J,0)) -> 1.55 | U10: =IFERROR(T10-S10,0) -> -3.3611364 | V10: =COUNTIF(Collection!A:A,J10)+COUNTIF(Sold!A:A,J10) -> 1 | W10: =IFERROR(_xlfn.TEXTAFTER(_xlfn.XLOOKUP(J10,Collection!A:A,Collection!C:C,),"Cards "),_xlfn.TEXTAFTER(_xlfn.XLOOKUP(J10,Sold!A:A,Sold!C:C,),"Cards ")) -> 2021 Panini Donruss Optic Splash | X10: =IFERROR(_xlfn.XLOOKUP(J10,Collection!A:A,Collection!B:B,),_xlfn.XLOOKUP(J10,Sold!A:A,Sold!B:B,)) -> Luka Doncic #4 | Y10: . | AB10: hotmamajamacards | AC10: 1.88
B11: R | C11: kenjay_cards | D11: 46146 | E11: 233 | F11: 3 | G11: 0.45 | H11: 0.36 | I11: Cade | J11: 3782640 | K11: 328 | L11: https://www.whatnot.com/order/JieocTtxhoCCzfkGLnBz49 | M11: whatnot.com/order/JieocTtxhoCCzfkGLnBz49 $3.00 + $0.45 (Shared Shipping) + $0.35 Tax = Total of $3.81 | N11: =IFERROR(_xlfn.TEXTAFTER(L11,"https://www."),"")&CHAR(10)&_xlfn.CONCAT(TEXT(F11,"$0.00")," + ",TEXT(P11,"$0.00")," (Shared Shipping) + ",TEXT(R11,"$0.00")," Tax = Total of ",TEXT(S11,"$0.00")) -> whatnot.com/order/JieocTtxhoCCzfkGLnBz49 $3.00 + $0.45 (Shared Shipping) + $0.35 Tax = Total of $3.81 | O11: =SUM(F11:H11) -> 3.81 | P11: =SUMIFS(G:G,C:C,C11,D:D,D11)/COUNTIFS(C:C,C11,D:D,D11) -> 0.45454545 | Q11: =+F11+P11 -> 3.4545455 | R11: =IF(H11=0,0,Q11*0.1025) -> 0.35409091 | S11: =+Q11+R11 -> 3.8086364 | T11: =IFERROR(_xlfn.XLOOKUP(J11,Collection!A:A,Collection!D:D,0)/100/_xlfn.XLOOKUP(J11,Collection!A:A,Collection!J:J,0),_xlfn.XLOOKUP(J11,Sold!A:A,Sold!D:D,0)/100/_xlfn.XLOOKUP(J11,Sold!A:A,Sold!J:J,0)) -> 1.46 | U11: =IFERROR(T11-S11,0) -> -2.3486364 | V11: =COUNTIF(Collection!A:A,J11)+COUNTIF(Sold!A:A,J11) -> 1 | W11: =IFERROR(_xlfn.TEXTAFTER(_xlfn.XLOOKUP(J11,Collection!A:A,Collection!C:C,),"Cards "),_xlfn.TEXTAFTER(_xlfn.XLOOKUP(J11,Sold!A:A,Sold!C:C,),"Cards ")) -> 2021 Panini Prizm Emergent | X11: =IFERROR(_xlfn.XLOOKUP(J11,Collection!A:A,Collection!B:B,),_xlfn.XLOOKUP(J11,Sold!A:A,Sold!B:B,)) -> Cade Cunningham #22 | Y11: . | AB11: noketownstar32 | AC11: 1.583275
B12: R | C12: kenjay_cards | D12: 46146 | E12: 234 | F12: 3 | G12: 0 | H12: 0.31 | I12: Luka | J12: 5289892 | K12: 311 | L12: https://www.whatnot.com/order/YdoZr7RTzDToYz6PByf22R | M12: whatnot.com/order/YdoZr7RTzDToYz6PByf22R $3.00 + $0.45 (Shared Shipping) + $0.35 Tax = Total of $3.81 | N12: =IFERROR(_xlfn.TEXTAFTER(L12,"https://www."),"")&CHAR(10)&_xlfn.CONCAT(TEXT(F12,"$0.00")," + ",TEXT(P12,"$0.00")," (Shared Shipping) + ",TEXT(R12,"$0.00")," Tax = Total of ",TEXT(S12,"$0.00")) -> whatnot.com/order/YdoZr7RTzDToYz6PByf22R $3.00 + $0.45 (Shared Shipping) + $0.35 Tax = Total of $3.81 | O12: =SUM(F12:H12) -> 3.31 | P12: =SUMIFS(G:G,C:C,C12,D:D,D12)/COUNTIFS(C:C,C12,D:D,D12) -> 0.45454545 | Q12: =+F12+P12 -> 3.4545455 | R12: =IF(H12=0,0,Q12*0.1025) -> 0.35409091 | S12: =+Q12+R12 -> 3.8086364 | T12: =IFERROR(_xlfn.XLOOKUP(J12,Collection!A:A,Collection!D:D,0)/100/_xlfn.XLOOKUP(J12,Collection!A:A,Collection!J:J,0),_xlfn.XLOOKUP(J12,Sold!A:A,Sold!D:D,0)/100/_xlfn.XLOOKUP(J12,Sold!A:A,Sold!J:J,0)) -> 1.86 | U12: =IFERROR(T12-S12,0) -> -1.9486364 | V12: =COUNTIF(Collection!A:A,J12)+COUNTIF(Sold!A:A,J12) -> 1 | W12: =IFERROR(_xlfn.TEXTAFTER(_xlfn.XLOOKUP(J12,Collection!A:A,Collection!C:C,),"Cards "),_xlfn.TEXTAFTER(_xlfn.XLOOKUP(J12,Sold!A:A,Sold!C:C,),"Cards ")) -> 2022 Panini Donruss Optic T Minus 3 2 1 | X12: =IFERROR(_xlfn.XLOOKUP(J12,Collection!A:A,Collection!B:B,),_xlfn.XLOOKUP(J12,Sold!A:A,Sold!B:B,)) -> Luka Doncic [Purple] #7 | Y12: . | AB12: card_fire | AC12: 1
B13: R | C13: kenjay_cards | D13: 46146 | E13: 242 | F13: 1 | G13: 0 | H13: 0.11 | I13: Gafford | J13: 11473930 | K13: 134 | L13: https://www.whatnot.com/order/fsZrqS9c5o3n2dqHjHqttF | M13: whatnot.com/order/fsZrqS9c5o3n2dqHjHqttF $1.00 + $0.45 (Shared Shipping) + $0.15 Tax = Total of $1.60 | N13: =IFERROR(_xlfn.TEXTAFTER(L13,"https://www."),"")&CHAR(10)&_xlfn.CONCAT(TEXT(F13,"$0.00")," + ",TEXT(P13,"$0.00")," (Shared Shipping) + ",TEXT(R13,"$0.00")," Tax = Total of ",TEXT(S13,"$0.00")) -> whatnot.com/order/fsZrqS9c5o3n2dqHjHqttF $1.00 + $0.45 (Shared Shipping) + $0.15 Tax = Total of $1.60 | O13: =SUM(F13:H13) -> 1.11 | P13: =SUMIFS(G:G,C:C,C13,D:D,D13)/COUNTIFS(C:C,C13,D:D,D13) -> 0.45454545 | Q13: =+F13+P13 -> 1.4545455 | R13: =IF(H13=0,0,Q13*0.1025) -> 0.14909091 | S13: =+Q13+R13 -> 1.6036364 | T13: =IFERROR(_xlfn.XLOOKUP(J13,Collection!A:A,Collection!D:D,0)/100/_xlfn.XLOOKUP(J13,Collection!A:A,Collection!J:J,0),_xlfn.XLOOKUP(J13,Sold!A:A,Sold!D:D,0)/100/_xlfn.XLOOKUP(J13,Sold!A:A,Sold!J:J,0)) -> 4.01 | U13: =IFERROR(T13-S13,0) -> 2.4063636 | V13: =COUNTIF(Collection!A:A,J13)+COUNTIF(Sold!A:A,J13) -> 1 | W13: =IFERROR(_xlfn.TEXTAFTER(_xlfn.XLOOKUP(J13,Collection!A:A,Collection!C:C,),"Cards "),_xlfn.TEXTAFTER(_xlfn.XLOOKUP(J13,Sold!A:A,Sold!C:C,),"Cards ")) -> 2025 Topps Chrome | X13: =IFERROR(_xlfn.XLOOKUP(J13,Collection!A:A,Collection!B:B,),_xlfn.XLOOKUP(J13,Sold!A:A,Sold!B:B,)) -> Daniel Gafford [Purple Refractor] #78 | Y13: . | AB13: blakewaldron4 | AC13: 1
B14: R | C14: kenjay_cards | D14: 46146 | E14: 276 | F14: 1 | G14: 0.2 | H14: 0.12 | I14: Murray | J14: 5178537 | K14: 394 | L14: https://www.whatnot.com/order/XWP5KdeeCdt8TKjdVmH5ek | M14: whatnot.com/order/XWP5KdeeCdt8TKjdVmH5ek $1.00 + $0.45 (Shared Shipping) + $0.15 Tax = Total of $1.60 | N14: =IFERROR(_xlfn.TEXTAFTER(L14,"https://www."),"")&CHAR(10)&_xlfn.CONCAT(TEXT(F14,"$0.00")," + ",TEXT(P14,"$0.00")," (Shared Shipping) + ",TEXT(R14,"$0.00")," Tax = Total of ",TEXT(S14,"$0.00")) -> whatnot.com/order/XWP5KdeeCdt8TKjdVmH5ek $1.00 + $0.45 (Shared Shipping) + $0.15 Tax = Total of $1.60 | O14: =SUM(F14:H14) -> 1.32 | P14: =SUMIFS(G:G,C:C,C14,D:D,D14)/COUNTIFS(C:C,C14,D:D,D14) -> 0.45454545 | Q14: =+F14+P14 -> 1.4545455 | R14: =IF(H14=0,0,Q14*0.1025) -> 0.14909091 | S14: =+Q14+R14 -> 1.6036364 | T14: =IFERROR(_xlfn.XLOOKUP(J14,Collection!A:A,Collection!D:D,0)/100/_xlfn.XLOOKUP(J14,Collection!A:A,Collection!J:J,0),_xlfn.XLOOKUP(J14,Sold!A:A,Sold!D:D,0)/100/_xlfn.XLOOKUP(J14,Sold!A:A,Sold!J:J,0)) -> 1.55 | U14: =IFERROR(T14-S14,0) -> -0.053636364 | V14: =COUNTIF(Collection!A:A,J14)+COUNTIF(Sold!A:A,J14) -> 1 | W14: =IFERROR(_xlfn.TEXTAFTER(_xlfn.XLOOKUP(J14,Collection!A:A,Collection!C:C,),"Cards "),_xlfn.TEXTAFTER(_xlfn.XLOOKUP(J14,Sold!A:A,Sold!C:C,),"Cards ")) -> 2022 Panini Contenders Suite Shots | X14: =IFERROR(_xlfn.XLOOKUP(J14,Collection!A:A,Collection!B:B,),_xlfn.XLOOKUP(J14,Sold!A:A,Sold!B:B,)) -> Jamal Murray #9 | Y14: . | AB14: peba_66 | AC14: 0.68345
B15: R | C15: kenjay_cards | D15: 46146 | E15: 289 | F15: 4 | G15: 0 | H15: 0.41 | I15: Luka | J15: 5463744 | K15: 584 | L15: https://www.whatnot.com/order/hQVu9JLwFefwSJcu3QwY6E | M15: whatnot.com/order/hQVu9JLwFefwSJcu3QwY6E $4.00 + $0.45 (Shared Shipping) + $0.46 Tax = Total of $4.91 | N15: =IFERROR(_xlfn.TEXTAFTER(L15,"https://www."),"")&CHAR(10)&_xlfn.CONCAT(TEXT(F15,"$0.00")," + ",TEXT(P15,"$0.00")," (Shared Shipping) + ",TEXT(R15,"$0.00")," Tax = Total of ",TEXT(S15,"$0.00")) -> whatnot.com/order/hQVu9JLwFefwSJcu3QwY6E $4.00 + $0.45 (Shared Shipping) + $0.46 Tax = Total of $4.91 | O15: =SUM(F15:H15) -> 4.41 | P15: =SUMIFS(G:G,C:C,C15,D:D,D15)/COUNTIFS(C:C,C15,D:D,D15) -> 0.45454545 | Q15: =+F15+P15 -> 4.4545455 | R15: =IF(H15=0,0,Q15*0.1025) -> 0.45659091 | S15: =+Q15+R15 -> 4.9111364 | T15: =IFERROR(_xlfn.XLOOKUP(J15,Collection!A:A,Collection!D:D,0)/100/_xlfn.XLOOKUP(J15,Collection!A:A,Collection!J:J,0),_xlfn.XLOOKUP(J15,Sold!A:A,Sold!D:D,0)/100/_xlfn.XLOOKUP(J15,Sold!A:A,Sold!J:J,0)) -> 0.62 | U15: =IFERROR(T15-S15,0) -> -4.2911364 | V15: =COUNTIF(Collection!A:A,J15)+COUNTIF(Sold!A:A,J15) -> 1 | W15: =IFERROR(_xlfn.TEXTAFTER(_xlfn.XLOOKUP(J15,Collection!A:A,Collection!C:C,),"Cards "),_xlfn.TEXTAFTER(_xlfn.XLOOKUP(J15,Sold!A:A,Sold!C:C,),"Cards ")) -> 2022 Panini Select | X15: =IFERROR(_xlfn.XLOOKUP(J15,Collection!A:A,Collection!B:B,),_xlfn.XLOOKUP(J15,Sold!A:A,Sold!B:B,)) -> Luka Doncic #151 | Y15: . | AB15: kassab_cards | AC15: 0.442525
B16: R | C16: kenjay_cards | D16: 46146 | E16: 293 | F16: 2 | G16: 0 | H16: 0.21 | I16: Jokic | J16: 10190248 | K16: 443 | L16: https://www.whatnot.com/order/HWhpJLX6J4h4DZZVCaeVYr | M16: whatnot.com/order/HWhpJLX6J4h4DZZVCaeVYr $2.00 + $0.45 (Shared Shipping) + $0.25 Tax = Total of $2.71 | N16: =IFERROR(_xlfn.TEXTAFTER(L16,"https://www."),"")&CHAR(10)&_xlfn.CONCAT(TEXT(F16,"$0.00")," + ",TEXT(P16,"$0.00")," (Shared Shipping) + ",TEXT(R16,"$0.00")," Tax = Total of ",TEXT(S16,"$0.00")) -> whatnot.com/order/HWhpJLX6J4h4DZZVCaeVYr $2.00 + $0.45 (Shared Shipping) + $0.25 Tax = Total of $2.71 | O16: =SUM(F16:H16) -> 2.21 | P16: =SUMIFS(G:G,C:C,C16,D:D,D16)/COUNTIFS(C:C,C16,D:D,D16) -> 0.45454545 | Q16: =+F16+P16 -> 2.4545455 | R16: =IF(H16=0,0,Q16*0.1025) -> 0.25159091 | S16: =+Q16+R16 -> 2.7061364 | T16: =IFERROR(_xlfn.XLOOKUP(J16,Collection!A:A,Collection!D:D,0)/100/_xlfn.XLOOKUP(J16,Collection!A:A,Collection!J:J,0),_xlfn.XLOOKUP(J16,Sold!A:A,Sold!D:D,0)/100/_xlfn.XLOOKUP(J16,Sold!A:A,Sold!J:J,0)) -> 1.47 | U16: =IFERROR(T16-S16,0) -> -1.2361364 | V16: =COUNTIF(Collection!A:A,J16)+COUNTIF(Sold!A:A,J16) -> 1 | W16: =IFERROR(_xlfn.TEXTAFTER(_xlfn.XLOOKUP(J16,Collection!A:A,Collection!C:C,),"Cards "),_xlfn.TEXTAFTER(_xlfn.XLOOKUP(J16,Sold!A:A,Sold!C:C,),"Cards ")) -> 2024 Panini Donruss Optic | X16: =IFERROR(_xlfn.XLOOKUP(J16,Collection!A:A,Collection!B:B,),_xlfn.XLOOKUP(J16,Sold!A:A,Sold!B:B,)) -> Nikola Jokic [Hyper Pink] #100 | Y16: . | AB16: sbgcards | AC16: 0.410775
B17: R | C17: kenjay_cards | D17: 46146 | E17: 302 | F17: 5 | G17: 0 | H17: 0.52 | I17: Reaves | J17: 3727445 | K17: 274 | L17: https://www.whatnot.com/order/o3mHoMSnpC2X8C3j6r4tiK | M17: whatnot.com/order/o3mHoMSnpC2X8C3j6r4tiK $5.00 + $0.45 (Shared Shipping) + $0.56 Tax = Total of $6.01 | N17: =IFERROR(_xlfn.TEXTAFTER(L17,"https://www."),"")&CHAR(10)&_xlfn.CONCAT(TEXT(F17,"$0.00")," + ",TEXT(P17,"$0.00")," (Shared Shipping) + ",TEXT(R17,"$0.00")," Tax = Total of ",TEXT(S17,"$0.00")) -> whatnot.com/order/o3mHoMSnpC2X8C3j6r4tiK $5.00 + $0.45 (Shared Shipping) + $0.56 Tax = Total of $6.01 | O17: =SUM(F17:H17) -> 5.52 | P17: =SUMIFS(G:G,C:C,C17,D:D,D17)/COUNTIFS(C:C,C17,D:D,D17) -> 0.45454545 | Q17: =+F17+P17 -> 5.4545455 | R17: =IF(H17=0,0,Q17*0.1025) -> 0.55909091 | S17: =+Q17+R17 -> 6.0136364 | T17: =IFERROR(_xlfn.XLOOKUP(J17,Collection!A:A,Collection!D:D,0)/100/_xlfn.XLOOKUP(J17,Collection!A:A,Collection!J:J,0),_xlfn.XLOOKUP(J17,Sold!A:A,Sold!D:D,0)/100/_xlfn.XLOOKUP(J17,Sold!A:A,Sold!J:J,0)) -> 2.37 | U17: =IFERROR(T17-S17,0) -> -3.6436364 | V17: =COUNTIF(Collection!A:A,J17)+COUNTIF(Sold!A:A,J17) -> 1 | W17: =IFERROR(_xlfn.TEXTAFTER(_xlfn.XLOOKUP(J17,Collection!A:A,Collection!C:C,),"Cards "),_xlfn.TEXTAFTER(_xlfn.XLOOKUP(J17,Sold!A:A,Sold!C:C,),"Cards ")) -> 2021 Panini Prizm | X17: =IFERROR(_xlfn.XLOOKUP(J17,Collection!A:A,Collection!B:B,),_xlfn.XLOOKUP(J17,Sold!A:A,Sold!B:B,)) -> Austin Reaves #165 | Y17: . | AB17: demarco210 | AC17: 0.28755
B18: R | C18: kenjay_cards | D18: 46146 | E18: 352 | F18: 5 | G18: 0 | H18: 0.52 | I18: Ant | J18: 3401118 | K18: 290 | L18: https://www.whatnot.com/order/3bymbw4YA5kuEYFfvvyWw2 | M18: whatnot.com/order/3bymbw4YA5kuEYFfvvyWw2 $5.00 + $0.45 (Shared Shipping) + $0.56 Tax = Total of $6.01 | N18: =IFERROR(_xlfn.TEXTAFTER(L18,"https://www."),"")&CHAR(10)&_xlfn.CONCAT(TEXT(F18,"$0.00")," + ",TEXT(P18,"$0.00")," (Shared Shipping) + ",TEXT(R18,"$0.00")," Tax = Total of ",TEXT(S18,"$0.00")) -> whatnot.com/order/3bymbw4YA5kuEYFfvvyWw2 $5.00 + $0.45 (Shared Shipping) + $0.56 Tax = Total of $6.01 | O18: =SUM(F18:H18) -> 5.52 | P18: =SUMIFS(G:G,C:C,C18,D:D,D18)/COUNTIFS(C:C,C18,D:D,D18) -> 0.45454545 | Q18: =+F18+P18 -> 5.4545455 | R18: =IF(H18=0,0,Q18*0.1025) -> 0.55909091 | S18: =+Q18+R18 -> 6.0136364 | T18: =IFERROR(_xlfn.XLOOKUP(J18,Collection!A:A,Collection!D:D,0)/100/_xlfn.XLOOKUP(J18,Collection!A:A,Collection!J:J,0),_xlfn.XLOOKUP(J18,Sold!A:A,Sold!D:D,0)/100/_xlfn.XLOOKUP(J18,Sold!A:A,Sold!J:J,0)) -> 1.7 | U18: =IFERROR(T18-S18,0) -> -4.3136364 | V18: =COUNTIF(Collection!A:A,J18)+COUNTIF(Sold!A:A,J18) -> 1 | W18: =IFERROR(_xlfn.TEXTAFTER(_xlfn.XLOOKUP(J18,Collection!A:A,Collection!C:C,),"Cards "),_xlfn.TEXTAFTER(_xlfn.XLOOKUP(J18,Sold!A:A,Sold!C:C,),"Cards ")) -> 2020 Panini Prizm Emergent | X18: =IFERROR(_xlfn.XLOOKUP(J18,Collection!A:A,Collection!B:B,),_xlfn.XLOOKUP(J18,Sold!A:A,Sold!B:B,)) -> Anthony Edwards #3 | Y18: . | AB18: kidds_cards | AC18: 0.15862353
B19: R | C19: Tanner346 | D19: 46145 | E19: 44 | F19: 3 | G19: 0.78 | H19: 0.39 | I19: Luka | J19: 4166936 | K19: 474 | L19: https://www.whatnot.com/order/gS3Pko5Lnk9cRAzYzXbJeF | M19: whatnot.com/order/gS3Pko5Lnk9cRAzYzXbJeF $3.00 + $0.36 (Shared Shipping) + $0.34 Tax = Total of $3.71 | N19: =IFERROR(_xlfn.TEXTAFTER(L19,"https://www."),"")&CHAR(10)&_xlfn.CONCAT(TEXT(F19,"$0.00")," + ",TEXT(P19,"$0.00")," (Shared Shipping) + ",TEXT(R19,"$0.00")," Tax = Total of ",TEXT(S19,"$0.00")) -> whatnot.com/order/gS3Pko5Lnk9cRAzYzXbJeF $3.00 + $0.36 (Shared Shipping) + $0.34 Tax = Total of $3.71 | O19: =SUM(F19:H19) -> 4.17 | P19: =SUMIFS(G:G,C:C,C19,D:D,D19)/COUNTIFS(C:C,C19,D:D,D19) -> 0.36333333 | Q19: =+F19+P19 -> 3.3633333 | R19: =IF(H19=0,0,Q19*0.1025) -> 0.34474167 | S19: =+Q19+R19 -> 3.708075 | T19: =IFERROR(_xlfn.XLOOKUP(J19,Collection!A:A,Collection!D:D,0)/100/_xlfn.XLOOKUP(J19,Collection!A:A,Collection!J:J,0),_xlfn.XLOOKUP(J19,Sold!A:A,Sold!D:D,0)/100/_xlfn.XLOOKUP(J19,Sold!A:A,Sold!J:J,0)) -> 1.3 | U19: =IFERROR(T19-S19,0) -> -2.408075 | V19: =COUNTIF(Collection!A:A,J19)+COUNTIF(Sold!A:A,J19) -> 1 | W19: =IFERROR(_xlfn.TEXTAFTER(_xlfn.XLOOKUP(J19,Collection!A:A,Collection!C:C,),"Cards "),_xlfn.TEXTAFTER(_xlfn.XLOOKUP(J19,Sold!A:A,Sold!C:C,),"Cards ")) -> 2021 Panini Chronicles | X19: =IFERROR(_xlfn.XLOOKUP(J19,Collection!A:A,Collection!B:B,),_xlfn.XLOOKUP(J19,Sold!A:A,Sold!B:B,)) -> Luka Doncic #304 | Y19: . | AB19: pbdreamlove | AC19: 0.1434125
... B28: R | C28: Tasrelics | D28: 46147 | E28: 10 | F28: 3 | G28: 0.4 | H28: 0.36 | I28: Embiid | J28: 131835 | K28: 125 | L28: https://www.whatnot.com/order/jhwwvPX5xZkZWVs8CGhFXe | M28: whatnot.com/order/jhwwvPX5xZkZWVs8CGhFXe $3.00 + $2.48 (Shared Shipping) + $0.56 Tax = Total of $6.04 | N28: =IFERROR(_xlfn.TEXTAFTER(L28,"https://www."),"")&CHAR(10)&_xlfn.CONCAT(TEXT(F28,"$0.00")," + ",TEXT(P28,"$0.00")," (Shared Shipping) + ",TEXT(R28,"$0.00")," Tax = Total of ",TEXT(S28,"$0.00")) -> whatnot.com/order/jhwwvPX5xZkZWVs8CGhFXe $3.00 + $2.48 (Shared Shipping) + $0.56 Tax = Total of $6.04 | O28: =SUM(F28:H28) -> 3.76 | P28: =SUMIFS(G:G,C:C,C28,D:D,D28)/COUNTIFS(C:C,C28,D:D,D28) -> 2.475 | Q28: =+F28+P28 -> 5.475 | R28: =IF(H28=0,0,Q28*0.1025) -> 0.5611875 | S28: =+Q28+R28 -> 6.0361875 | T28: =IFERROR(_xlfn.XLOOKUP(J28,Collection!A:A,Collection!D:D,0)/100/_xlfn.XLOOKUP(J28,Collection!A:A,Collection!J:J,0),_xlfn.XLOOKUP(J28,Sold!A:A,Sold!D:D,0)/100/_xlfn.XLOOKUP(J28,Sold!A:A,Sold!J:J,0)) -> 5.56 | U28: =IFERROR(T28-S28,0) -> -0.4761875 | V28: =COUNTIF(Collection!A:A,J28)+COUNTIF(Sold!A:A,J28) -> 1 | W28: =IFERROR(_xlfn.TEXTAFTER(_xlfn.XLOOKUP(J28,Collection!A:A,Collection!C:C,),"Cards "),_xlfn.TEXTAFTER(_xlfn.XLOOKUP(J28,Sold!A:A,Sold!C:C,),"Cards ")) -> 2014 Panini Hoops | X28: =IFERROR(_xlfn.XLOOKUP(J28,Collection!A:A,Collection!B:B,),_xlfn.XLOOKUP(J28,Sold!A:A,Sold!B:B,)) -> Joel Embiid #263 | Y28: . | AB28: dcollectorsclub | AC28: -1.17745
B29: R | C29: djbsports | D29: 46148 | E29: 93 | F29: 1 | G29: 1.09 | H29: 0.22 | I29: Wade | L29: https://www.whatnot.com/order/ZQa92YACdaqMGpqFzdMcVG | M29: whatnot.com/order/ZQa92YACdaqMGpqFzdMcVG $1.00 + $1.09 (Shared Shipping) + $0.21 Tax = Total of $2.30 | N29: =IFERROR(_xlfn.TEXTAFTER(L29,"https://www."),"")&CHAR(10)&_xlfn.CONCAT(TEXT(F29,"$0.00")," + ",TEXT(P29,"$0.00")," (Shared Shipping) + ",TEXT(R29,"$0.00")," Tax = Total of ",TEXT(S29,"$0.00")) -> whatnot.com/order/ZQa92YACdaqMGpqFzdMcVG $1.00 + $1.09 (Shared Shipping) + $0.21 Tax = Total of $2.30 | O29: =SUM(F29:H29) -> 2.31 | P29: =SUMIFS(G:G,C:C,C29,D:D,D29)/COUNTIFS(C:C,C29,D:D,D29) -> 1.09 | Q29: =+F29+P29 -> 2.09 | R29: =IF(H29=0,0,Q29*0.1025) -> 0.214225 | S29: =+Q29+R29 -> 2.304225 | T29: =IFERROR(_xlfn.XLOOKUP(J29,Collection!A:A,Collection!D:D,0)/100/_xlfn.XLOOKUP(J29,Collection!A:A,Collection!J:J,0),_xlfn.XLOOKUP(J29,Sold!A:A,Sold!D:D,0)/100/_xlfn.XLOOKUP(J29,Sold!A:A,Sold!J:J,0)) -> #DIV/0! | U29: =IFERROR(T29-S29,0) -> 0 | V29: =COUNTIF(Collection!A:A,J29)+COUNTIF(Sold!A:A,J29) -> 0 | W29: =IFERROR(_xlfn.TEXTAFTER(_xlfn.XLOOKUP(J29,Collection!A:A,Collection!C:C,),"Cards "),_xlfn.TEXTAFTER(_xlfn.XLOOKUP(J29,Sold!A:A,Sold!C:C,),"Cards ")) -> #N/A | X29: =IFERROR(_xlfn.XLOOKUP(J29,Collection!A:A,Collection!B:B,),_xlfn.XLOOKUP(J29,Sold!A:A,Sold!B:B,)) -> 0 | Y29: Not Listed | AB29: cardyoinkers | AC29: -1.56495
B30: R | C30: iceball | D30: 46148 | E30: 45 | F30: 5 | G30: 4.35 | H30: 0.97 | I30: Reaves | J30: 8776006 | K30: 253 | L30: https://www.whatnot.com/order/9ki7HURGVDFpQYLubozunU | M30: whatnot.com/order/9ki7HURGVDFpQYLubozunU $5.00 + $0.21 (Shared Shipping) + $0.53 Tax = Total of $5.74 | N30: =IFERROR(_xlfn.TEXTAFTER(L30,"https://www."),"")&CHAR(10)&_xlfn.CONCAT(TEXT(F30,"$0.00")," + ",TEXT(P30,"$0.00")," (Shared Shipping) + ",TEXT(R30,"$0.00")," Tax = Total of ",TEXT(S30,"$0.00")) -> whatnot.com/order/9ki7HURGVDFpQYLubozunU $5.00 + $0.21 (Shared Shipping) + $0.53 Tax = Total of $5.74 | O30: =SUM(F30:H30) -> 10.32 | P30: =SUMIFS(G:G,C:C,C30,D:D,D30)/COUNTIFS(C:C,C30,D:D,D30) -> 0.20714286 | Q30: =+F30+P30 -> 5.2071429 | R30: =IF(H30=0,0,Q30*0.1025) -> 0.53373214 | S30: =+Q30+R30 -> 5.740875 | T30: =IFERROR(_xlfn.XLOOKUP(J30,Collection!A:A,Collection!D:D,0)/100/_xlfn.XLOOKUP(J30,Collection!A:A,Collection!J:J,0),_xlfn.XLOOKUP(J30,Sold!A:A,Sold!D:D,0)/100/_xlfn.XLOOKUP(J30,Sold!A:A,Sold!J:J,0)) -> 2.13 | U30: =IFERROR(T30-S30,0) -> -3.610875 | V30: =COUNTIF(Collection!A:A,J30)+COUNTIF(Sold!A:A,J30) -> 1 | W30: =IFERROR(_xlfn.TEXTAFTER(_xlfn.XLOOKUP(J30,Collection!A:A,Collection!C:C,),"Cards "),_xlfn.TEXTAFTER(_xlfn.XLOOKUP(J30,Sold!A:A,Sold!C:C,),"Cards ")) -> 2024 Panini Donruss | X30: =IFERROR(_xlfn.XLOOKUP(J30,Collection!A:A,Collection!B:B,),_xlfn.XLOOKUP(J30,Sold!A:A,Sold!B:B,)) -> Austin Reaves [Storm] #163 | Y30: . | AB30: iceball | AC30: -2.2392542
B31: R | C31: iceball | D31: 46148 | E31: 109 | F31: 15 | G31: 0 | H31: 1.54 | I31: Jokic | J31: 95721 | K31: 51082129 | L31: https://www.whatnot.com/order/27RrZ5UcQbAp2yynBpazpE | M31: whatnot.com/order/27RrZ5UcQbAp2yynBpazpE $15.00 + $0.21 (Shared Shipping) + $1.56 Tax = Total of $16.77 | N31: =IFERROR(_xlfn.TEXTAFTER(L31,"https://www."),"")&CHAR(10)&_xlfn.CONCAT(TEXT(F31,"$0.00")," + ",TEXT(P31,"$0.00")," (Shared Shipping) + ",TEXT(R31,"$0.00")," Tax = Total of ",TEXT(S31,"$0.00")) -> whatnot.com/order/27RrZ5UcQbAp2yynBpazpE $15.00 + $0.21 (Shared Shipping) + $1.56 Tax = Total of $16.77 | O31: =SUM(F31:H31) -> 16.54 | P31: =SUMIFS(G:G,C:C,C31,D:D,D31)/COUNTIFS(C:C,C31,D:D,D31) -> 0.20714286 | Q31: =+F31+P31 -> 15.207143 | R31: =IF(H31=0,0,Q31*0.1025) -> 1.5587321 | S31: =+Q31+R31 -> 16.765875 | T31: =IFERROR(_xlfn.XLOOKUP(J31,Collection!A:A,Collection!D:D,0)/100/_xlfn.XLOOKUP(J31,Collection!A:A,Collection!J:J,0),_xlfn.XLOOKUP(J31,Sold!A:A,Sold!D:D,0)/100/_xlfn.XLOOKUP(J31,Sold!A:A,Sold!J:J,0)) -> 19.52 | U31: =IFERROR(T31-S31,0) -> 2.754125 | V31: =COUNTIF(Collection!A:A,J31)+COUNTIF(Sold!A:A,J31) -> 1 | W31: =IFERROR(_xlfn.TEXTAFTER(_xlfn.XLOOKUP(J31,Collection!A:A,Collection!C:C,),"Cards "),_xlfn.TEXTAFTER(_xlfn.XLOOKUP(J31,Sold!A:A,Sold!C:C,),"Cards ")) -> 2019 Panini Prizm | X31: =IFERROR(_xlfn.XLOOKUP(J31,Collection!A:A,Collection!B:B,),_xlfn.XLOOKUP(J31,Sold!A:A,Sold!B:B,)) -> Nikola Jokic [Ruby Wave Prizm] #84 | Y31: . | AB31: Tanner346 | AC31: -2.434225
B32: R | C32: iceball | D32: 46148 | E32: Givvy 4 | F32: 0 | G32: 0 | H32: 0 | I32: James | J32: 9781694 | K32: 335 | L32: https://www.whatnot.com/order/9Nw32iaBQX4B786bgpSBCs | M32: whatnot.com/order/9Nw32iaBQX4B786bgpSBCs $0.00 + $0.21 (Shared Shipping) + $0.02 Tax = Total of $0.23 | N32: =IFERROR(_xlfn.TEXTAFTER(L32,"https://www."),"")&CHAR(10)&_xlfn.CONCAT(TEXT(F32,"$0.00")," + ",TEXT(P32,"$0.00")," (Shared Shipping) + ",TEXT(R32,"$0.00")," Tax = Total of ",TEXT(S32,"$0.00")) -> whatnot.com/order/9Nw32iaBQX4B786bgpSBCs $0.00 + $0.21 (Shared Shipping) + $0.00 Tax = Total of $0.21 | O32: =SUM(F32:H32) -> 0 | P32: =SUMIFS(G:G,C:C,C32,D:D,D32)/COUNTIFS(C:C,C32,D:D,D32) -> 0.20714286 | Q32: =+F32+P32 -> 0.20714286 | R32: =IF(H32=0,0,Q32*0.1025) -> 0 | S32: =+Q32+R32 -> 0.20714286 | T32: =IFERROR(_xlfn.XLOOKUP(J32,Collection!A:A,Collection!D:D,0)/100/_xlfn.XLOOKUP(J32,Collection!A:A,Collection!J:J,0),_xlfn.XLOOKUP(J32,Sold!A:A,Sold!D:D,0)/100/_xlfn.XLOOKUP(J32,Sold!A:A,Sold!J:J,0)) -> 1.68 | U32: =IFERROR(T32-S32,0) -> 1.4728571 | V32: =COUNTIF(Collection!A:A,J32)+COUNTIF(Sold!A:A,J32) -> 1 | W32: =IFERROR(_xlfn.TEXTAFTER(_xlfn.XLOOKUP(J32,Collection!A:A,Collection!C:C,),"Cards "),_xlfn.TEXTAFTER(_xlfn.XLOOKUP(J32,Sold!A:A,Sold!C:C,),"Cards ")) -> 2024 Panini Select | X32: =IFERROR(_xlfn.XLOOKUP(J32,Collection!A:A,Collection!B:B,),_xlfn.XLOOKUP(J32,Sold!A:A,Sold!B:B,)) -> LeBron James [Blue Prizm] #54 | Y32: Verify Parallel - LeBron James [Blue Prizm] #54 - 2024 Panini Select | AB32: sycotik | AC32: -2.5945
B33: R | C33: iceball | D33: 46148 | E33: Givvy 4 | F33: 0 | G33: 0 | H33: 0 | I33: Brown | J33: 10198347 | K33: 537 | L33: https://www.whatnot.com/order/9Nw32iaBQX4B786bgpSBCs | M33: whatnot.com/order/9Nw32iaBQX4B786bgpSBCs $0.00 + $0.21 (Shared Shipping) + $0.02 Tax = Total of $0.23 | N33: =IFERROR(_xlfn.TEXTAFTER(L33,"https://www."),"")&CHAR(10)&_xlfn.CONCAT(TEXT(F33,"$0.00")," + ",TEXT(P33,"$0.00")," (Shared Shipping) + ",TEXT(R33,"$0.00")," Tax = Total of ",TEXT(S33,"$0.00")) -> whatnot.com/order/9Nw32iaBQX4B786bgpSBCs $0.00 + $0.21 (Shared Shipping) + $0.00 Tax = Total of $0.21 | O33: =SUM(F33:H33) -> 0 | P33: =SUMIFS(G:G,C:C,C33,D:D,D33)/COUNTIFS(C:C,C33,D:D,D33) -> 0.20714286 | Q33: =+F33+P33 -> 0.20714286 | R33: =IF(H33=0,0,Q33*0.1025) -> 0 | S33: =+Q33+R33 -> 0.20714286 | T33: =IFERROR(_xlfn.XLOOKUP(J33,Collection!A:A,Collection!D:D,0)/100/_xlfn.XLOOKUP(J33,Collection!A:A,Collection!J:J,0),_xlfn.XLOOKUP(J33,Sold!A:A,Sold!D:D,0)/100/_xlfn.XLOOKUP(J33,Sold!A:A,Sold!J:J,0)) -> 1 | U33: =IFERROR(T33-S33,0) -> 0.79285714 | V33: =COUNTIF(Collection!A:A,J33)+COUNTIF(Sold!A:A,J33) -> 1 | W33: =IFERROR(_xlfn.TEXTAFTER(_xlfn.XLOOKUP(J33,Collection!A:A,Collection!C:C,),"Cards "),_xlfn.TEXTAFTER(_xlfn.XLOOKUP(J33,Sold!A:A,Sold!C:C,),"Cards ")) -> 2024 Panini Donruss Optic | X33: =IFERROR(_xlfn.XLOOKUP(J33,Collection!A:A,Collection!B:B,),_xlfn.XLOOKUP(J33,Sold!A:A,Sold!B:B,)) -> Jaylen Brown [Purple] #206 | Y33: . | AB33: ronnierippzcards | AC33: -2.66745
B34: R | C34: iceball | D34: 46148 | E34: Givvy 4 | F34: 0 | G34: 0 | H34: 0 | I34: Sheppard | J34: 9782911 | K34: 298 | L34: https://www.whatnot.com/order/9Nw32iaBQX4B786bgpSBCs | M34: whatnot.com/order/9Nw32iaBQX4B786bgpSBCs $0.00 + $0.21 (Shared Shipping) + $0.02 Tax = Total of $0.23 | N34: =IFERROR(_xlfn.TEXTAFTER(L34,"https://www."),"")&CHAR(10)&_xlfn.CONCAT(TEXT(F34,"$0.00")," + ",TEXT(P34,"$0.00")," (Shared Shipping) + ",TEXT(R34,"$0.00")," Tax = Total of ",TEXT(S34,"$0.00")) -> whatnot.com/order/9Nw32iaBQX4B786bgpSBCs $0.00 + $0.21 (Shared Shipping) + $0.00 Tax = Total of $0.21 | O34: =SUM(F34:H34) -> 0 | P34: =SUMIFS(G:G,C:C,C34,D:D,D34)/COUNTIFS(C:C,C34,D:D,D34) -> 0.20714286 | Q34: =+F34+P34 -> 0.20714286 | R34: =IF(H34=0,0,Q34*0.1025) -> 0 | S34: =+Q34+R34 -> 0.20714286 | T34: =IFERROR(_xlfn.XLOOKUP(J34,Collection!A:A,Collection!D:D,0)/100/_xlfn.XLOOKUP(J34,Collection!A:A,Collection!J:J,0),_xlfn.XLOOKUP(J34,Sold!A:A,Sold!D:D,0)/100/_xlfn.XLOOKUP(J34,Sold!A:A,Sold!J:J,0)) -> 1.82 | U34: =IFERROR(T34-S34,0) -> 1.6128571 | V34: =COUNTIF(Collection!A:A,J34)+COUNTIF(Sold!A:A,J34) -> 1 | W34: =IFERROR(_xlfn.TEXTAFTER(_xlfn.XLOOKUP(J34,Collection!A:A,Collection!C:C,),"Cards "),_xlfn.TEXTAFTER(_xlfn.XLOOKUP(J34,Sold!A:A,Sold!C:C,),"Cards ")) -> 2024 Panini Select | X34: =IFERROR(_xlfn.XLOOKUP(J34,Collection!A:A,Collection!B:B,),_xlfn.XLOOKUP(J34,Sold!A:A,Sold!B:B,)) -> Reed Sheppard [Blue Cracked Ice Prizm] #68 | Y34: . | AB34: cardseal | AC34: -2.8825
B35: R | C35: iceball | D35: 46148 | E35: Givvy 4 | F35: 0 | G35: 0 | H35: 0 | I35: Curry | J35: 9265999 | K35: 377 | L35: https://www.whatnot.com/order/9Nw32iaBQX4B786bgpSBCs | M35: whatnot.com/order/9Nw32iaBQX4B786bgpSBCs $0.00 + $0.21 (Shared Shipping) + $0.02 Tax = Total of $0.23 | N35: =IFERROR(_xlfn.TEXTAFTER(L35,"https://www."),"")&CHAR(10)&_xlfn.CONCAT(TEXT(F35,"$0.00")," + ",TEXT(P35,"$0.00")," (Shared Shipping) + ",TEXT(R35,"$0.00")," Tax = Total of ",TEXT(S35,"$0.00")) -> whatnot.com/order/9Nw32iaBQX4B786bgpSBCs $0.00 + $0.21 (Shared Shipping) + $0.00 Tax = Total of $0.21 | O35: =SUM(F35:H35) -> 0 | P35: =SUMIFS(G:G,C:C,C35,D:D,D35)/COUNTIFS(C:C,C35,D:D,D35) -> 0.20714286 | Q35: =+F35+P35 -> 0.20714286 | R35: =IF(H35=0,0,Q35*0.1025) -> 0 | S35: =+Q35+R35 -> 0.20714286 | T35: =IFERROR(_xlfn.XLOOKUP(J35,Collection!A:A,Collection!D:D,0)/100/_xlfn.XLOOKUP(J35,Collection!A:A,Collection!J:J,0),_xlfn.XLOOKUP(J35,Sold!A:A,Sold!D:D,0)/100/_xlfn.XLOOKUP(J35,Sold!A:A,Sold!J:J,0)) -> 1.71 | U35: =IFERROR(T35-S35,0) -> 1.5028571 | V35: =COUNTIF(Collection!A:A,J35)+COUNTIF(Sold!A:A,J35) -> 1 | W35: =IFERROR(_xlfn.TEXTAFTER(_xlfn.XLOOKUP(J35,Collection!A:A,Collection!C:C,),"Cards "),_xlfn.TEXTAFTER(_xlfn.XLOOKUP(J35,Sold!A:A,Sold!C:C,),"Cards ")) -> 2024 Panini Revolution Hardwood Legacy | X35: =IFERROR(_xlfn.XLOOKUP(J35,Collection!A:A,Collection!B:B,),_xlfn.XLOOKUP(J35,Sold!A:A,Sold!B:B,)) -> Stephen Curry #3 | Y35: Verify Parallel - Stephen Curry #3 - 2024 Panini Revolution Hardwood Legac | AB35: kadenjc1 | AC35: -3.511375
B36: R | C36: iceball | D36: 46148 | E36: 125 | F36: 2.36 | G36: 0 | H36: 0.24 | I36: Luka | J36: 8406896 | K36: 515 | L36: https://www.whatnot.com/order/N3ommW2GZtgbdFUhrqPhaC | M36: whatnot.com/order/N3ommW2GZtgbdFUhrqPhaC $2.36 + $0.21 (Shared Shipping) + $0.26 Tax = Total of $2.83 | N36: =IFERROR(_xlfn.TEXTAFTER(L36,"https://www."),"")&CHAR(10)&_xlfn.CONCAT(TEXT(F36,"$0.00")," + ",TEXT(P36,"$0.00")," (Shared Shipping) + ",TEXT(R36,"$0.00")," Tax = Total of ",TEXT(S36,"$0.00")) -> whatnot.com/order/N3ommW2GZtgbdFUhrqPhaC $2.36 + $0.21 (Shared Shipping) + $0.26 Tax = Total of $2.83 | O36: =SUM(F36:H36) -> 2.6 | P36: =SUMIFS(G:G,C:C,C36,D:D,D36)/COUNTIFS(C:C,C36,D:D,D36) -> 0.20714286 | Q36: =+F36+P36 -> 2.5671429 | R36: =IF(H36=0,0,Q36*0.1025) -> 0.26313214 | S36: =+Q36+R36 -> 2.830275 | T36: =IFERROR(_xlfn.XLOOKUP(J36,Collection!A:A,Collection!D:D,0)/100/_xlfn.XLOOKUP(J36,Collection!A:A,Collection!J:J,0),_xlfn.XLOOKUP(J36,Sold!A:A,Sold!D:D,0)/100/_xlfn.XLOOKUP(J36,Sold!A:A,Sold!J:J,0)) -> 1.02 | U36: =IFERROR(T36-S36,0) -> -1.810275 | V36: =COUNTIF(Collection!A:A,J36)+COUNTIF(Sold!A:A,J36) -> 1 | W36: =IFERROR(_xlfn.TEXTAFTER(_xlfn.XLOOKUP(J36,Collection!A:A,Collection!C:C,),"Cards "),_xlfn.TEXTAFTER(_xlfn.XLOOKUP(J36,Sold!A:A,Sold!C:C,),"Cards ")) -> 2024 Panini NBA Hoops Frequent Flyers | X36: =IFERROR(_xlfn.XLOOKUP(J36,Collection!A:A,Collection!B:B,),_xlfn.XLOOKUP(J36,Sold!A:A,Sold!B:B,)) -> Luka Doncic #3 | Y36: . | AB36: millenniumcards | AC36: -3.654725
B37: R | C37: iceball | D37: 46148 | E37: 125 | F37: 2.33 | G37: 0 | H37: 0.24 | I37: Luka | J37: 8537640 | K37: 361 | L37: https://www.whatnot.com/order/N3ommW2GZtgbdFUhrqPhaC | M37: whatnot.com/order/N3ommW2GZtgbdFUhrqPhaC $2.33 + $0.21 (Shared Shipping) + $0.26 Tax = Total of $2.80 | N37: =IFERROR(_xlfn.TEXTAFTER(L37,"https://www."),"")&CHAR(10)&_xlfn.CONCAT(TEXT(F37,"$0.00")," + ",TEXT(P37,"$0.00")," (Shared Shipping) + ",TEXT(R37,"$0.00")," Tax = Total of ",TEXT(S37,"$0.00")) -> whatnot.com/order/N3ommW2GZtgbdFUhrqPhaC $2.33 + $0.21 (Shared Shipping) + $0.26 Tax = Total of $2.80 | O37: =SUM(F37:H37) -> 2.57 | P37: =SUMIFS(G:G,C:C,C37,D:D,D37)/COUNTIFS(C:C,C37,D:D,D37) -> 0.20714286 | Q37: =+F37+P37 -> 2.5371429 | R37: =IF(H37=0,0,Q37*0.1025) -> 0.26005714 | S37: =+Q37+R37 -> 2.7972 | T37: =IFERROR(_xlfn.XLOOKUP(J37,Collection!A:A,Collection!D:D,0)/100/_xlfn.XLOOKUP(J37,Collection!A:A,Collection!J:J,0),_xlfn.XLOOKUP(J37,Sold!A:A,Sold!D:D,0)/100/_xlfn.XLOOKUP(J37,Sold!A:A,Sold!J:J,0)) -> 1.71 | U37: =IFERROR(T37-S37,0) -> -1.0872 | V37: =COUNTIF(Collection!A:A,J37)+COUNTIF(Sold!A:A,J37) -> 1 | W37: =IFERROR(_xlfn.TEXTAFTER(_xlfn.XLOOKUP(J37,Collection!A:A,Collection!C:C,),"Cards "),_xlfn.TEXTAFTER(_xlfn.XLOOKUP(J37,Sold!A:A,Sold!C:C,),"Cards ")) -> 2024 Panini Prizm | X37: =IFERROR(_xlfn.XLOOKUP(J37,Collection!A:A,Collection!B:B,),_xlfn.XLOOKUP(J37,Sold!A:A,Sold!B:B,)) -> Luka Doncic #89 | Y37: . | AB37: Hoot2000 | AC37: -4.0947812
B38: R | C38: iceball | D38: 46148 | E38: 125 | F38: 2.33 | G38: 0 | H38: 0.24 | I38: Luka | J38: 2948779 | K38: 365 | L38: https://www.whatnot.com/order/N3ommW2GZtgbdFUhrqPhaC | M38: whatnot.com/order/N3ommW2GZtgbdFUhrqPhaC $2.33 + $0.21 (Shared Shipping) + $0.26 Tax = Total of $2.80 | N38: =IFERROR(_xlfn.TEXTAFTER(L38,"https://www."),"")&CHAR(10)&_xlfn.CONCAT(TEXT(F38,"$0.00")," + ",TEXT(P38,"$0.00")," (Shared Shipping) + ",TEXT(R38,"$0.00")," Tax = Total of ",TEXT(S38,"$0.00")) -> whatnot.com/order/N3ommW2GZtgbdFUhrqPhaC $2.33 + $0.21 (Shared Shipping) + $0.26 Tax = Total of $2.80 | O38: =SUM(F38:H38) -> 2.57 | P38: =SUMIFS(G:G,C:C,C38,D:D,D38)/COUNTIFS(C:C,C38,D:D,D38) -> 0.20714286 | Q38: =+F38+P38 -> 2.5371429 | R38: =IF(H38=0,0,Q38*0.1025) -> 0.26005714 | S38: =+Q38+R38 -> 2.7972 | T38: =IFERROR(_xlfn.XLOOKUP(J38,Collection!A:A,Collection!D:D,0)/100/_xlfn.XLOOKUP(J38,Collection!A:A,Collection!J:J,0),_xlfn.XLOOKUP(J38,Sold!A:A,Sold!D:D,0)/100/_xlfn.XLOOKUP(J38,Sold!A:A,Sold!J:J,0)) -> 1.74 | U38: =IFERROR(T38-S38,0) -> -1.0572 | V38: =COUNTIF(Collection!A:A,J38)+COUNTIF(Sold!A:A,J38) -> 1 | W38: =IFERROR(_xlfn.TEXTAFTER(_xlfn.XLOOKUP(J38,Collection!A:A,Collection!C:C,),"Cards "),_xlfn.TEXTAFTER(_xlfn.XLOOKUP(J38,Sold!A:A,Sold!C:C,),"Cards ")) -> 2020 Panini Chronicles | X38: =IFERROR(_xlfn.XLOOKUP(J38,Collection!A:A,Collection!B:B,),_xlfn.XLOOKUP(J38,Sold!A:A,Sold!B:B,)) -> Luka Doncic [Pink] #228 | Y38: . | AB38: brash1986 | AC38: -4.41835
B39: R | C39: iceball | D39: 46148 | E39: 125 | F39: 2.33 | G39: 0 | H39: 0.24 | I39: Luka | J39: 6834778 | K39: 312 | L39: https://www.whatnot.com/order/N3ommW2GZtgbdFUhrqPhaC | M39: whatnot.com/order/N3ommW2GZtgbdFUhrqPhaC $2.33 + $0.21 (Shared Shipping) + $0.26 Tax = Total of $2.80 | N39: =IFERROR(_xlfn.TEXTAFTER(L39,"https://www."),"")&CHAR(10)&_xlfn.CONCAT(TEXT(F39,"$0.00")," + ",TEXT(P39,"$0.00")," (Shared Shipping) + ",TEXT(R39,"$0.00")," Tax = Total of ",TEXT(S39,"$0.00")) -> whatnot.com/order/N3ommW2GZtgbdFUhrqPhaC $2.33 + $0.21 (Shared Shipping) + $0.26 Tax = Total of $2.80 | O39: =SUM(F39:H39) -> 2.57 | P39: =SUMIFS(G:G,C:C,C39,D:D,D39)/COUNTIFS(C:C,C39,D:D,D39) -> 0.20714286 | Q39: =+F39+P39 -> 2.5371429 | R39: =IF(H39=0,0,Q39*0.1025) -> 0.26005714 | S39: =+Q39+R39 -> 2.7972 | T39: =IFERROR(_xlfn.XLOOKUP(J39,Collection!A:A,Collection!D:D,0)/100/_xlfn.XLOOKUP(J39,Collection!A:A,Collection!J:J,0),_xlfn.XLOOKUP(J39,Sold!A:A,Sold!D:D,0)/100/_xlfn.XLOOKUP(J39,Sold!A:A,Sold!J:J,0)) -> 2.05 | U39: =IFERROR(T39-S39,0) -> -0.7472 | V39: =COUNTIF(Collection!A:A,J39)+COUNTIF(Sold!A:A,J39) -> 1 | W39: =IFERROR(_xlfn.TEXTAFTER(_xlfn.XLOOKUP(J39,Collection!A:A,Collection!C:C,),"Cards "),_xlfn.TEXTAFTER(_xlfn.XLOOKUP(J39,Sold!A:A,Sold!C:C,),"Cards ")) -> 2023 Donruss Optic Express Lane | X39: =IFERROR(_xlfn.XLOOKUP(J39,Collection!A:A,Collection!B:B,),_xlfn.XLOOKUP(J39,Sold!A:A,Sold!B:B,)) -> Luka Doncic [Purple] #13 | Y39: Verify Parallel | AB39: wadek2332 | AC39: -4.420875
B40: R | C40: iceball | D40: 46148 | E40: 125 | F40: 2.33 | G40: 0 | H40: 0.24 | I40: Luka | J40: 2946119 | K40: 281 | L40: https://www.whatnot.com/order/N3ommW2GZtgbdFUhrqPhaC | M40: whatnot.com/order/N3ommW2GZtgbdFUhrqPhaC $2.33 + $0.21 (Shared Shipping) + $0.26 Tax = Total of $2.80 | N40: =IFERROR(_xlfn.TEXTAFTER(L40,"https://www."),"")&CHAR(10)&_xlfn.CONCAT(TEXT(F40,"$0.00")," + ",TEXT(P40,"$0.00")," (Shared Shipping) + ",TEXT(R40,"$0.00")," Tax = Total of ",TEXT(S40,"$0.00")) -> whatnot.com/order/N3ommW2GZtgbdFUhrqPhaC $2.33 + $0.21 (Shared Shipping) + $0.26 Tax = Total of $2.80 | O40: =SUM(F40:H40) -> 2.57 | P40: =SUMIFS(G:G,C:C,C40,D:D,D40)/COUNTIFS(C:C,C40,D:D,D40) -> 0.20714286 | Q40: =+F40+P40 -> 2.5371429 | R40: =IF(H40=0,0,Q40*0.1025) -> 0.26005714 | S40: =+Q40+R40 -> 2.7972 | T40: =IFERROR(_xlfn.XLOOKUP(J40,Collection!A:A,Collection!D:D,0)/100/_xlfn.XLOOKUP(J40,Collection!A:A,Collection!J:J,0),_xlfn.XLOOKUP(J40,Sold!A:A,Sold!D:D,0)/100/_xlfn.XLOOKUP(J40,Sold!A:A,Sold!J:J,0)) -> 1.99 | U40: =IFERROR(T40-S40,0) -> -0.8072 | V40: =COUNTIF(Collection!A:A,J40)+COUNTIF(Sold!A:A,J40) -> 1 | W40: =IFERROR(_xlfn.TEXTAFTER(_xlfn.XLOOKUP(J40,Collection!A:A,Collection!C:C,),"Cards "),_xlfn.TEXTAFTER(_xlfn.XLOOKUP(J40,Sold!A:A,Sold!C:C,),"Cards ")) -> 2020 Panini Chronicles | X40: =IFERROR(_xlfn.XLOOKUP(J40,Collection!A:A,Collection!B:B,),_xlfn.XLOOKUP(J40,Sold!A:A,Sold!B:B,)) -> Luka Doncic #519 | Y40: . | AB40: jjcards23 | AC40: -4.47065
B41: R | C41: iceball | D41: 46148 | E41: 125 | F41: 2.33 | G41: 0 | H41: 0.24 | I41: Luka | J41: 11360390 | K41: 599 | L41: https://www.whatnot.com/order/N3ommW2GZtgbdFUhrqPhaC | M41: whatnot.com/order/N3ommW2GZtgbdFUhrqPhaC $2.33 + $0.21 (Shared Shipping) + $0.26 Tax = Total of $2.80 | N41: =IFERROR(_xlfn.TEXTAFTER(L41,"https://www."),"")&CHAR(10)&_xlfn.CONCAT(TEXT(F41,"$0.00")," + ",TEXT(P41,"$0.00")," (Shared Shipping) + ",TEXT(R41,"$0.00")," Tax = Total of ",TEXT(S41,"$0.00")) -> whatnot.com/order/N3ommW2GZtgbdFUhrqPhaC $2.33 + $0.21 (Shared Shipping) + $0.26 Tax = Total of $2.80 | O41: =SUM(F41:H41) -> 2.57 | P41: =SUMIFS(G:G,C:C,C41,D:D,D41)/COUNTIFS(C:C,C41,D:D,D41) -> 0.20714286 | Q41: =+F41+P41 -> 2.5371429 | R41: =IF(H41=0,0,Q41*0.1025) -> 0.26005714 | S41: =+Q41+R41 -> 2.7972 | T41: =IFERROR(_xlfn.XLOOKUP(J41,Collection!A:A,Collection!D:D,0)/100/_xlfn.XLOOKUP(J41,Collection!A:A,Collection!J:J,0),_xlfn.XLOOKUP(J41,Sold!A:A,Sold!D:D,0)/100/_xlfn.XLOOKUP(J41,Sold!A:A,Sold!J:J,0)) -> 0 | U41: =IFERROR(T41-S41,0) -> -2.7972 | V41: =COUNTIF(Collection!A:A,J41)+COUNTIF(Sold!A:A,J41) -> 1 | W41: =IFERROR(_xlfn.TEXTAFTER(_xlfn.XLOOKUP(J41,Collection!A:A,Collection!C:C,),"Cards "),_xlfn.TEXTAFTER(_xlfn.XLOOKUP(J41,Sold!A:A,Sold!C:C,),"Cards ")) -> 2020 Panini Chronicles Hometown Heroes Rookie Autographs | X41: =IFERROR(_xlfn.XLOOKUP(J41,Collection!A:A,Collection!B:B,),_xlfn.XLOOKUP(J41,Sold!A:A,Sold!B:B,)) -> Luka Doncic #554 | Y41: . | AB41: grazicards | AC41: -4.683875
B42: R | C42: iceball | D42: 46148 | E42: 125 | F42: 2.33 | G42: 0 | H42: 0.24 | I42: Luka | J42: 5001342 | K42: 362 | L42: https://www.whatnot.com/order/N3ommW2GZtgbdFUhrqPhaC | M42: whatnot.com/order/N3ommW2GZtgbdFUhrqPhaC $2.33 + $0.21 (Shared Shipping) + $0.26 Tax = Total of $2.80 | N42: =IFERROR(_xlfn.TEXTAFTER(L42,"https://www."),"")&CHAR(10)&_xlfn.CONCAT(TEXT(F42,"$0.00")," + ",TEXT(P42,"$0.00")," (Shared Shipping) + ",TEXT(R42,"$0.00")," Tax = Total of ",TEXT(S42,"$0.00")) -> whatnot.com/order/N3ommW2GZtgbdFUhrqPhaC $2.33 + $0.21 (Shared Shipping) + $0.26 Tax = Total of $2.80 | O42: =SUM(F42:H42) -> 2.57 | P42: =SUMIFS(G:G,C:C,C42,D:D,D42)/COUNTIFS(C:C,C42,D:D,D42) -> 0.20714286 | Q42: =+F42+P42 -> 2.5371429 | R42: =IF(H42=0,0,Q42*0.1025) -> 0.26005714 | S42: =+Q42+R42 -> 2.7972 | T42: =IFERROR(_xlfn.XLOOKUP(J42,Collection!A:A,Collection!D:D,0)/100/_xlfn.XLOOKUP(J42,Collection!A:A,Collection!J:J,0),_xlfn.XLOOKUP(J42,Sold!A:A,Sold!D:D,0)/100/_xlfn.XLOOKUP(J42,Sold!A:A,Sold!J:J,0)) -> 1.67 | U42: =IFERROR(T42-S42,0) -> -1.1272 | V42: =COUNTIF(Collection!A:A,J42)+COUNTIF(Sold!A:A,J42) -> 1 | W42: =IFERROR(_xlfn.TEXTAFTER(_xlfn.XLOOKUP(J42,Collection!A:A,Collection!C:C,),"Cards "),_xlfn.TEXTAFTER(_xlfn.XLOOKUP(J42,Sold!A:A,Sold!C:C,),"Cards ")) -> 2022 Panini Donruss Magicians | X42: =IFERROR(_xlfn.XLOOKUP(J42,Collection!A:A,Collection!B:B,),_xlfn.XLOOKUP(J42,Sold!A:A,Sold!B:B,)) -> Luka Doncic #2 | Y42: . | AB42: ritchievault | AC42: -5.0730417
B43: R | C43: iceball | D43: 46148 | E43: 125 | F43: 2.33 | G43: 0 | H43: 0.24 | I43: Luka | J43: N/A | L43: https://www.whatnot.com/order/N3ommW2GZtgbdFUhrqPhaC | M43: whatnot.com/order/N3ommW2GZtgbdFUhrqPhaC $2.33 + $0.21 (Shared Shipping) + $0.26 Tax = Total of $2.80 | N43: =IFERROR(_xlfn.TEXTAFTER(L43,"https://www."),"")&CHAR(10)&_xlfn.CONCAT(TEXT(F43,"$0.00")," + ",TEXT(P43,"$0.00")," (Shared Shipping) + ",TEXT(R43,"$0.00")," Tax = Total of ",TEXT(S43,"$0.00")) -> whatnot.com/order/N3ommW2GZtgbdFUhrqPhaC $2.33 + $0.21 (Shared Shipping) + $0.26 Tax = Total of $2.80 | O43: =SUM(F43:H43) -> 2.57 | P43: =SUMIFS(G:G,C:C,C43,D:D,D43)/COUNTIFS(C:C,C43,D:D,D43) -> 0.20714286 | Q43: =+F43+P43 -> 2.5371429 | R43: =IF(H43=0,0,Q43*0.1025) -> 0.26005714 | S43: =+Q43+R43 -> 2.7972 | T43: =IFERROR(_xlfn.XLOOKUP(J43,Collection!A:A,Collection!D:D,0)/100/_xlfn.XLOOKUP(J43,Collection!A:A,Collection!J:J,0),_xlfn.XLOOKUP(J43,Sold!A:A,Sold!D:D,0)/100/_xlfn.XLOOKUP(J43,Sold!A:A,Sold!J:J,0)) -> #DIV/0! | U43: =IFERROR(T43-S43,0) -> 0 | V43: =COUNTIF(Collection!A:A,J43)+COUNTIF(Sold!A:A,J43) -> 0 | W43: =IFERROR(_xlfn.TEXTAFTER(_xlfn.XLOOKUP(J43,Collection!A:A,Collection!C:C,),"Cards "),_xlfn.TEXTAFTER(_xlfn.XLOOKUP(J43,Sold!A:A,Sold!C:C,),"Cards ")) -> #N/A | X43: =IFERROR(_xlfn.XLOOKUP(J43,Collection!A:A,Collection!B:B,),_xlfn.XLOOKUP(J43,Sold!A:A,Sold!B:B,)) -> #N/A | Y43: Not listed | AB43: Tasrelics | AC43: -5.512375
B44: R | C44: iceball | D44: 46148 | E44: 125 | F44: 2.33 | G44: 0 | H44: 0.24 | I44: Luka | J44: 6284400 | K44: 436 | L44: https://www.whatnot.com/order/N3ommW2GZtgbdFUhrqPhaC | M44: whatnot.com/order/N3ommW2GZtgbdFUhrqPhaC $2.33 + $0.21 (Shared Shipping) + $0.26 Tax = Total of $2.80 | N44: =IFERROR(_xlfn.TEXTAFTER(L44,"https://www."),"")&CHAR(10)&_xlfn.CONCAT(TEXT(F44,"$0.00")," + ",TEXT(P44,"$0.00")," (Shared Shipping) + ",TEXT(R44,"$0.00")," Tax = Total of ",TEXT(S44,"$0.00")) -> whatnot.com/order/N3ommW2GZtgbdFUhrqPhaC $2.33 + $0.21 (Shared Shipping) + $0.26 Tax = Total of $2.80 | O44: =SUM(F44:H44) -> 2.57 | P44: =SUMIFS(G:G,C:C,C44,D:D,D44)/COUNTIFS(C:C,C44,D:D,D44) -> 0.20714286 | Q44: =+F44+P44 -> 2.5371429 | R44: =IF(H44=0,0,Q44*0.1025) -> 0.26005714 | S44: =+Q44+R44 -> 2.7972 | T44: =IFERROR(_xlfn.XLOOKUP(J44,Collection!A:A,Collection!D:D,0)/100/_xlfn.XLOOKUP(J44,Collection!A:A,Collection!J:J,0),_xlfn.XLOOKUP(J44,Sold!A:A,Sold!D:D,0)/100/_xlfn.XLOOKUP(J44,Sold!A:A,Sold!J:J,0)) -> 1.21 | U44: =IFERROR(T44-S44,0) -> -1.5872 | V44: =COUNTIF(Collection!A:A,J44)+COUNTIF(Sold!A:A,J44) -> 1 | W44: =IFERROR(_xlfn.TEXTAFTER(_xlfn.XLOOKUP(J44,Collection!A:A,Collection!C:C,),"Cards "),_xlfn.TEXTAFTER(_xlfn.XLOOKUP(J44,Sold!A:A,Sold!C:C,),"Cards ")) -> 2023 Panini Donruss | X44: =IFERROR(_xlfn.XLOOKUP(J44,Collection!A:A,Collection!B:B,),_xlfn.XLOOKUP(J44,Sold!A:A,Sold!B:B,)) -> Luka Doncic #141 | Y44: . | AB44: jurcar | AC44: -6.0411591
B45: R | C45: iceball | D45: 46148 | E45: 126 | F45: 2.5 | G45: 0 | H45: 0.26 | I45: Luka | J45: 6422084 | K45: 387 | L45: https://www.whatnot.com/order/8DwoNWn73teh8obUuAY5eP | M45: whatnot.com/order/8DwoNWn73teh8obUuAY5eP $2.50 + $0.21 (Shared Shipping) + $0.28 Tax = Total of $2.98 | N45: =IFERROR(_xlfn.TEXTAFTER(L45,"https://www."),"")&CHAR(10)&_xlfn.CONCAT(TEXT(F45,"$0.00")," + ",TEXT(P45,"$0.00")," (Shared Shipping) + ",TEXT(R45,"$0.00")," Tax = Total of ",TEXT(S45,"$0.00")) -> whatnot.com/order/8DwoNWn73teh8obUuAY5eP $2.50 + $0.21 (Shared Shipping) + $0.28 Tax = Total of $2.98 | O45: =SUM(F45:H45) -> 2.76 | P45: =SUMIFS(G:G,C:C,C45,D:D,D45)/COUNTIFS(C:C,C45,D:D,D45) -> 0.20714286 | Q45: =+F45+P45 -> 2.7071429 | R45: =IF(H45=0,0,Q45*0.1025) -> 0.27748214 | S45: =+Q45+R45 -> 2.984625 | T45: =IFERROR(_xlfn.XLOOKUP(J45,Collection!A:A,Collection!D:D,0)/100/_xlfn.XLOOKUP(J45,Collection!A:A,Collection!J:J,0),_xlfn.XLOOKUP(J45,Sold!A:A,Sold!D:D,0)/100/_xlfn.XLOOKUP(J45,Sold!A:A,Sold!J:J,0)) -> 1.58 | U45: =IFERROR(T45-S45,0) -> -1.404625 | V45: =COUNTIF(Collection!A:A,J45)+COUNTIF(Sold!A:A,J45) -> 1 | W45: =IFERROR(_xlfn.TEXTAFTER(_xlfn.XLOOKUP(J45,Collection!A:A,Collection!C:C,),"Cards "),_xlfn.TEXTAFTER(_xlfn.XLOOKUP(J45,Sold!A:A,Sold!C:C,),"Cards ")) -> 2023 Panini Prizm Global Reach | X45: =IFERROR(_xlfn.XLOOKUP(J45,Collection!A:A,Collection!B:B,),_xlfn.XLOOKUP(J45,Sold!A:A,Sold!B:B,)) -> Luka Doncic #1 | Y45: . | AB45: gogreen_sportscards | AC45: -6.8176
B46: R | C46: iceball | D46: 46148 | E46: 126 | F46: 2.5 | G46: 0 | H46: 0.26 | I46: Luka | J46: 9265985 | K46: 378 | L46: https://www.whatnot.com/order/8DwoNWn73teh8obUuAY5eP | M46: whatnot.com/order/8DwoNWn73teh8obUuAY5eP $2.50 + $0.21 (Shared Shipping) + $0.28 Tax = Total of $2.98 | N46: =IFERROR(_xlfn.TEXTAFTER(L46,"https://www."),"")&CHAR(10)&_xlfn.CONCAT(TEXT(F46,"$0.00")," + ",TEXT(P46,"$0.00")," (Shared Shipping) + ",TEXT(R46,"$0.00")," Tax = Total of ",TEXT(S46,"$0.00")) -> whatnot.com/order/8DwoNWn73teh8obUuAY5eP $2.50 + $0.21 (Shared Shipping) + $0.28 Tax = Total of $2.98 | O46: =SUM(F46:H46) -> 2.76 | P46: =SUMIFS(G:G,C:C,C46,D:D,D46)/COUNTIFS(C:C,C46,D:D,D46) -> 0.20714286 | Q46: =+F46+P46 -> 2.7071429 | R46: =IF(H46=0,0,Q46*0.1025) -> 0.27748214 | S46: =+Q46+R46 -> 2.984625 | T46: =IFERROR(_xlfn.XLOOKUP(J46,Collection!A:A,Collection!D:D,0)/100/_xlfn.XLOOKUP(J46,Collection!A:A,Collection!J:J,0),_xlfn.XLOOKUP(J46,Sold!A:A,Sold!D:D,0)/100/_xlfn.XLOOKUP(J46,Sold!A:A,Sold!J:J,0)) -> 1.69 | U46: =IFERROR(T46-S46,0) -> -1.294625 | V46: =COUNTIF(Collection!A:A,J46)+COUNTIF(Sold!A:A,J46) -> 1 | W46: =IFERROR(_xlfn.TEXTAFTER(_xlfn.XLOOKUP(J46,Collection!A:A,Collection!C:C,),"Cards "),_xlfn.TEXTAFTER(_xlfn.XLOOKUP(J46,Sold!A:A,Sold!C:C,),"Cards ")) -> 2024 Panini Revolution Hardwood Legacy | X46: =IFERROR(_xlfn.XLOOKUP(J46,Collection!A:A,Collection!B:B,),_xlfn.XLOOKUP(J46,Sold!A:A,Sold!B:B,)) -> Luka Doncic #1 | Y46: . | AB46: jrtcardsandcollectibles | AC46: -7.011425
B47: R | C47: iceball | D47: 46148 | E47: 126 | F47: 2.5 | G47: 0 | H47: 0.26 | I47: Luka | J47: 10339925 | K47: 216 | L47: https://www.whatnot.com/order/8DwoNWn73teh8obUuAY5eP | M47: whatnot.com/order/8DwoNWn73teh8obUuAY5eP $2.50 + $0.21 (Shared Shipping) + $0.28 Tax = Total of $2.98 | N47: =IFERROR(_xlfn.TEXTAFTER(L47,"https://www."),"")&CHAR(10)&_xlfn.CONCAT(TEXT(F47,"$0.00")," + ",TEXT(P47,"$0.00")," (Shared Shipping) + ",TEXT(R47,"$0.00")," Tax = Total of ",TEXT(S47,"$0.00")) -> whatnot.com/order/8DwoNWn73teh8obUuAY5eP $2.50 + $0.21 (Shared Shipping) + $0.28 Tax = Total of $2.98 | O47: =SUM(F47:H47) -> 2.76 | P47: =SUMIFS(G:G,C:C,C47,D:D,D47)/COUNTIFS(C:C,C47,D:D,D47) -> 0.20714286 | Q47: =+F47+P47 -> 2.7071429 | R47: =IF(H47=0,0,Q47*0.1025) -> 0.27748214 | S47: =+Q47+R47 -> 2.984625 | T47: =IFERROR(_xlfn.XLOOKUP(J47,Collection!A:A,Collection!D:D,0)/100/_xlfn.XLOOKUP(J47,Collection!A:A,Collection!J:J,0),_xlfn.XLOOKUP(J47,Sold!A:A,Sold!D:D,0)/100/_xlfn.XLOOKUP(J47,Sold!A:A,Sold!J:J,0)) -> 2.32 | U47: =IFERROR(T47-S47,0) -> -0.664625 | V47: =COUNTIF(Collection!A:A,J47)+COUNTIF(Sold!A:A,J47) -> 1 | W47: =IFERROR(_xlfn.TEXTAFTER(_xlfn.XLOOKUP(J47,Collection!A:A,Collection!C:C,),"Cards "),_xlfn.TEXTAFTER(_xlfn.XLOOKUP(J47,Sold!A:A,Sold!C:C,),"Cards ")) -> 2024 Panini Mosaic Elevate | X47: =IFERROR(_xlfn.XLOOKUP(J47,Collection!A:A,Collection!B:B,),_xlfn.XLOOKUP(J47,Sold!A:A,Sold!B:B,)) -> Luka Doncic [Mosaic] #16 | Y47: 9959212 or 10339925 whats the difference | AB47: gerberlifebb | AC47: -9.218275
B48: R | C48: iceball | D48: 46148 | E48: 126 | F48: 2.5 | G48: 0 | H48: 0.26 | I48: Luka | J48: 6713723 | K48: 323 | L48: https://www.whatnot.com/order/8DwoNWn73teh8obUuAY5eP | M48: whatnot.com/order/8DwoNWn73teh8obUuAY5eP $2.50 + $0.21 (Shared Shipping) + $0.28 Tax = Total of $2.98 | N48: =IFERROR(_xlfn.TEXTAFTER(L48,"https://www."),"")&CHAR(10)&_xlfn.CONCAT(TEXT(F48,"$0.00")," + ",TEXT(P48,"$0.00")," (Shared Shipping) + ",TEXT(R48,"$0.00")," Tax = Total of ",TEXT(S48,"$0.00")) -> whatnot.com/order/8DwoNWn73teh8obUuAY5eP $2.50 + $0.21 (Shared Shipping) + $0.28 Tax = Total of $2.98 | O48: =SUM(F48:H48) -> 2.76 | P48: =SUMIFS(G:G,C:C,C48,D:D,D48)/COUNTIFS(C:C,C48,D:D,D48) -> 0.20714286 | Q48: =+F48+P48 -> 2.7071429 | R48: =IF(H48=0,0,Q48*0.1025) -> 0.27748214 | S48: =+Q48+R48 -> 2.984625 | T48: =IFERROR(_xlfn.XLOOKUP(J48,Collection!A:A,Collection!D:D,0)/100/_xlfn.XLOOKUP(J48,Collection!A:A,Collection!J:J,0),_xlfn.XLOOKUP(J48,Sold!A:A,Sold!D:D,0)/100/_xlfn.XLOOKUP(J48,Sold!A:A,Sold!J:J,0)) -> 1.35 | U48: =IFERROR(T48-S48,0) -> -1.634625 | V48: =COUNTIF(Collection!A:A,J48)+COUNTIF(Sold!A:A,J48) -> 1 | W48: =IFERROR(_xlfn.TEXTAFTER(_xlfn.XLOOKUP(J48,Collection!A:A,Collection!C:C,),"Cards "),_xlfn.TEXTAFTER(_xlfn.XLOOKUP(J48,Sold!A:A,Sold!C:C,),"Cards ")) -> 2023 Panini Select Thunder Lane | X48: =IFERROR(_xlfn.XLOOKUP(J48,Collection!A:A,Collection!B:B,),_xlfn.XLOOKUP(J48,Sold!A:A,Sold!B:B,)) -> Luka Doncic #3 | Y48: . | AB48: stealsndealscollectibles | AC48: -13.002475
...

Sheet Collection
A1: id | B1: product-name | C1: console-name | D1: price-in-pennies | E1: include-string | F1: condition-string | G1: sku | H1: notes | I1: cost-basis-in-pennies | J1: quantity | K1: date-entered | L1: date-purchased | M1: grading-company | N1: grading-cert-id | O1: folder | P1: Player Label | Q1: Set Name | R1: Variant | S1: Number | T1: Value | U1: PSV Player Label | V1: Status | W1: Count | X1: Tier | Y1: Desired Price | Z1: Minimum Price | AB1: Conditions | AC1: =COUNTBLANK(N1:N558) -> 0 | AE1: Average of Top 3 cards | AL1: Typos | AM1: Corrected
A2: 11484449 | B2: Cooper Flagg #251 | C2: Basketball Cards 2025 Topps Chrome | D2: 2104 | E2: Ungraded | F2: Normal wear | H2: eBay | I2: 2944 | J2: 1 | K2: 46133 | L2: 46132 | N2: 13 | P2: =TRIM(LEFT(B2, MIN(IFERROR(FIND("[", B2), LEN(B2)+1), IFERROR(FIND("#", B2), LEN(B2)+1)) - 1)) -> Cooper Flagg | Q2: =IFERROR(_xlfn.TEXTAFTER(_xlfn.XLOOKUP(A2,Collection!A:A,Collection!C:C,),"Cards "),C2) -> 2025 Topps Chrome | R2: =IFERROR(_xlfn.TEXTBEFORE(_xlfn.TEXTAFTER(B2, "["), "]"), "-") -> - | S2: =IFERROR(_xlfn.TEXTAFTER(_xlfn.XLOOKUP(A2,Collection!A:A,Collection!B:B,),"#"),"") -> 251 | T2: =D2/100 -> 21.04 | U2: Cooper Flagg | V2: =IF(ISNUMBER(MATCH(N2,Catalog!$B$4:$B$16, 0)), "Keep", "For Sale") -> Keep | W2: =COUNTIFS(V:V,"For Sale",A:A,A2) -> 1 | X2: =_xlfn.LET( _xlpm.val,_xlfn.XLOOKUP(U2,AE:AE,AG:AG,)/100, _xlpm.tier,IF(_xlpm.val<1,5,IF(_xlpm.val<2,4,IF(_xlpm.val<5,3,IF(_xlpm.val<10,2,1)))), _xlpm.tier) -> 1 | Y2: =_xlfn.LET( _xlpm.price, (MAX(I2,D2,25)/100)*(1+$AC$3), _xlpm.rounder, IF(_xlpm.price < 1.5, FLOOR(_xlpm.price, 0.25), IF(_xlpm.price < 2.5, MROUND(_xlpm.price, 0.5), MROUND(_xlpm.price, 1))), MAX(0.25, _xlpm.rounder)) -> 35 | Z2: =_xlfn.LET( _xlpm.price, IF(I2=0, IF(W2>1,1-$AC$2,1)*(D2/100), MIN(IF(W2>1,1-$AC$2,1)*(D2/100), IF(W2>1,1-$AC$2,1)*(I2/100))), _xlpm.rounder, IF(_xlpm.price < 1.5, FLOOR(_xlpm.price, 0.25), IF(_xlpm.price < 2.5, MROUND(_xlpm.price, 0.5), MROUND(_xlpm.price, 1))), MAX(0.25, _xlpm.rounder)) -> 21 | AB2: Double Discount | AC2: 0.15 | AL2: Luka DoncÌŒic | AM2: Luka Doncic
A3: 11484449 | B3: Cooper Flagg #251 | C3: Basketball Cards 2025 Topps Chrome | D3: 2104 | E3: Ungraded | F3: Normal wear | H3: "whatnot.com/order/JCCEshFbNE7KuEUh3Kjd6B_x000D_ $15.00 + $1.05 (Shared Shipping) + $1.65 Tax = Total of $17.70" | I3: 1770 | J3: 1 | K3: 46183 | L3: 46182 | N3: 14 | P3: =TRIM(LEFT(B3, MIN(IFERROR(FIND("[", B3), LEN(B3)+1), IFERROR(FIND("#", B3), LEN(B3)+1)) - 1)) -> Cooper Flagg | Q3: =IFERROR(_xlfn.TEXTAFTER(_xlfn.XLOOKUP(A3,Collection!A:A,Collection!C:C,),"Cards "),C3) -> 2025 Topps Chrome | R3: =IFERROR(_xlfn.TEXTBEFORE(_xlfn.TEXTAFTER(B3, "["), "]"), "-") -> - | S3: =IFERROR(_xlfn.TEXTAFTER(_xlfn.XLOOKUP(A3,Collection!A:A,Collection!B:B,),"#"),"") -> 251 | T3: =D3/100 -> 21.04 | U3: Cooper Flagg | V3: =IF(ISNUMBER(MATCH(N3,Catalog!$B$4:$B$16, 0)), "Keep", "For Sale") -> For Sale | W3: =COUNTIFS(V:V,"For Sale",A:A,A3) -> 1 | X3: =_xlfn.LET( _xlpm.val,_xlfn.XLOOKUP(U3,AE:AE,AG:AG,)/100, _xlpm.tier,IF(_xlpm.val<1,5,IF(_xlpm.val<2,4,IF(_xlpm.val<5,3,IF(_xlpm.val<10,2,1)))), _xlpm.tier) -> 1 | Y3: =_xlfn.LET( _xlpm.price, (MAX(I3,D3,25)/100)*(1+$AC$3), _xlpm.rounder, IF(_xlpm.price < 1.5, FLOOR(_xlpm.price, 0.25), IF(_xlpm.price < 2.5, MROUND(_xlpm.price, 0.5), MROUND(_xlpm.price, 1))), MAX(0.25, _xlpm.rounder)) -> 25 | Z3: =_xlfn.LET( _xlpm.price, IF(I3=0, IF(W3>1,1-$AC$2,1)*(D3/100), MIN(IF(W3>1,1-$AC$2,1)*(D3/100), IF(W3>1,1-$AC$2,1)*(I3/100))), _xlpm.rounder, IF(_xlpm.price < 1.5, FLOOR(_xlpm.price, 0.25), IF(_xlpm.price < 2.5, MROUND(_xlpm.price, 0.5), MROUND(_xlpm.price, 1))), MAX(0.25, _xlpm.rounder)) -> 18 | AB3: Desired Profit | AC3: 0.2 | AE3: PSV Player Label | AF3: id | AG3: Average of price-in-pennies | AI3: Row Labels | AJ3: Sum of quantity | AL3: Gheorghe MureÈ™an | AM3: Gheorghe Muresan
